Workbook

Sheet BC_DongTien_2026
A2: BÁO CÁO DÒNG TIỀN TÀI CHÍNH CÔNG TY
A3: TÌNH HÌNH HOẠT ĐỘNG 2026
A4: NGÀY CẬP NHẬT : 17/ 08/ 2026
A6: I | B6: TÀI CHÍNH | C6: NĂM 2025 | K6: NĂM 2026
A7: A | B7: TỔNG THU | C7: THÁNG 09 | E7: THÁNG 10 | G7: THÁNG 11 | I7: THÁNG 12 | K7: THÁNG 01 | M7: THÁNG 02 | O7: THÁNG 03 | Q7: THÁNG 04 | S7: THÁNG 05 | U7: THÁNG 06 | W7: THÁNG 07 | Y7: THÁNG 08 | AA7: THÁNG 09 | AC7: THÁNG 10 | AE7: THÁNG 11 | AG7: THÁNG 12
A8: Mã | B8: Tên công việc/ hạng mục | C8: Dự kiến | D8: Thực tế | E8: Dự kiến | F8: Thực tế | G8: Dự kiến | H8: Thực tế | I8: Dự kiến | J8: Thực tế | K8: Dự kiến | L8: Thực tế | M8: Dự kiến | N8: Thực tế | O8: Dự kiến | P8: Thực tế | Q8: Dự kiến | R8: Thực tế | S8: Dự kiến | T8: Thực tế | U8: Dự kiến | V8: Thực tế | W8: Dự kiến | X8: Thực tế | Y8: Dự kiến | Z8: Thực tế | AA8: Dự kiến | AB8: Thực tế | AC8: Dự kiến | AD8: Thực tế | AE8: Dự kiến | AF8: Thực tế | AG8: Dự kiến | AH8: Thực tế
A9: 1 | B9: Red Dragon | J9: =SUM(J10:J18) -> 176256000 | P9: =SUM(P10:P18) -> 220320000 | Y9: =SUM(Y10:Y18) -> 132192000 | AC9: =SUM(AC10:AC18) -> 220320000 | AG9: =SUM(AG10:AG18) -> 44064000
A10: 1.1 | B10: Sau khi ký hợp đồng | J10: =BC_ThuChi_2026!H10 -> 176256000
A11: 1.2 | B11: Nộp TKCS | P11: 220320000
A12: 1.3 | B12: Duyệt TKCS | Y12: =BC_ThuChi_2026!J12 -> 44064000
A13: 1.4 | B13: Lập hồ sơ PCCC - TKCS | Y13: =BC_ThuChi_2026!J13 -> 44064000
A14: 1.5 | B14: Lập hồ sơ PCCC - TKKT | Y14: =BC_ThuChi_2026!J14 -> 44064000
A15: 1.6 | B15: Nộp TKKT | AC15: =BC_ThuChi_2026!J15 -> 220320000
A16: 1.7 | B16: Duyệt TKKT | AG16: =BC_ThuChi_2026!J16 -> 44064000
A17: 1.8 | B17: Nộp TKTC
A18: 1.9 | B18: Duyệt TKTC
A19: 2 | B19: CCTP1 & CCTP 2 | N19: =N20 -> 639770400 | P19: =SUM(P20:P31) -> 639770400 | T19: =SUM(T20:T31) -> 319885200 | X19: =SUM(X20:X31) -> 639770400 | AA19: =SUM(AA20:AA31) -> 1599426000 | AC19: =SUM(AC20:AC31) -> 639770400 | AE19: =SUM(AE20:AE31) -> 319885200 | AG19: =SUM(AG20:AG31) -> 319885200
A20: 2.1 | B20: Phí huy động nhân sự | N20: =BC_ThuChi_2026!H21 -> 639770400
A21: 2.2 | B21: Hoàn thành kiểm tra và hoàn thiện thiết kế concept hiện hữu | P21: =BC_ThuChi_2026!H22 -> 639770400
A22: 2.3 | B22: Hoàn thành workshop với CĐT | T22: =BC_ThuChi_2026!H23 -> 319885200
A23: 2.4 | B23: Sau khi bên B nộp hồ sơ hardcopy TKCS cho bên A | X23: =BC_ThuChi_2026!H24 -> 639770400 | Y23: =BC_ThuChi_2026!J23 -> -
A24: 2.5 | B24: CĐT phê duyệt TKCS và có VB thẩm định TKCS | AA24: =BC_ThuChi_2026!J25 -> 639770400 | AC24: =BC_ThuChi_2026!J24 -> -
A25: 2.6 | B25: Sau khi bên B nộp hồ sơ hardcopy TKKT cho bên A | AA25: =BC_ThuChi_2026!J26 -> 639770400
A26: 2.7 | B26: Sau khi bên B nộp hồ sơ PCCC cho bên A | AA26: =BC_ThuChi_2026!J27 -> 319885200
A27: 2.8 | B27: Sau khi CĐT phê duyệt TKKT và PCCC | AC27: =BC_ThuChi_2026!J28 -> 639770400
A28: 2.9 | B28: Sau khi bên B nộp hồ sơ hardcopy TKTC ngầm cho bên A | AE28: =BC_ThuChi_2026!J29 -> 319885200
A29: 2.1 | B29: Sau khi bên B nộp hồ sơ hardcopy TKTC thân cho bên A | AG29: =BC_ThuChi_2026!J30 -> 319885200
A30: 2.11 | B30: Sau khi CĐT phê duyệt hồ sơ TKTC
A31: 2.12 | B31: Sau khi dự án hoàn thành, nghiệm thu và đưa vào sử dụng
A32: 3 | B32: C8A | R32: =SUM(R33:R43) -> 205465000 | AA32: =SUM(AA33:AA43) -> 199711980 | AC32: =SUM(AC33:AC43) -> 199711980 | AE32: =SUM(AE33:AE43) -> 199711980 | AG32: =SUM(AG33:AG43) -> 299567970
A33: 3.1 | B33: Tạm ứng | R33: =BC_ThuChi_2026!H35 -> 205465000
A34: 3.2 | B34: Hoàn thành workshop với CĐT | T34: =BC_ThuChi_2026!H36 -> 201355700
A35: 3.3 | B35: Sau khi bên B nộp hồ sơ hardcopy TKCS cho bên A | AA35: =BC_ThuChi_2026!J37 -> 199711980
A36: 3.4 | B36: CĐT phê duyệt TKCS và có VB thẩm định TKCS | AC36: =BC_ThuChi_2026!J38 -> 199711980
A37: 3.5 | B37: Sau khi bên B nộp hồ sơ PCCC cho bên A | AE37: =BC_ThuChi_2026!J39 -> 199711980
A38: 3.6 | B38: Sau khi bên B nộp hồ sơ hardcopy TKKT cho bên A | AG38: =BC_ThuChi_2026!J40 -> 299567970
A39: 3.7 | B39: Sau khi CĐT phê duyệt TKKT và PCCC
A40: 3.8 | B40: Sau khi bên B nộp hồ sơ hardcopy TKTC ngầm cho bên A
A41: 3.9 | B41: Sau khi bên B nộp hồ sơ hardcopy TKTC thân cho bên A
A42: 3.1 | B42: Sau khi CĐT phê duyệt hồ sơ TKTC
...

Sheet BC_ThuChi_2026
A2: BÁO CÁO TÀI CHÍNH CÔNG TY
A3: TÌNH HÌNH HOẠT ĐỘNG 2026
A4: NGÀY CẬP NHẬT : 17/ 08/ 2026
A6: I . TÀI CHÍNH | H6: THỰC TẾ | J6: DỰ KIẾN
A7: A | B7: TỔNG THU | H7: =SUM(H9,H20,H34,H47,H61) -> 3706793100 | J7: =SUM(J9,J20,J34,J47,J61) -> 11434222710
A8: Mã đối tượng | B8: Tên công việc/ hạng mục | C8: Giá trị HĐ (chưa VAT) | D8: Giá trị theo HĐ (gồm VAT) | E8: Tỷ lệ (%) | F8: Tạm Ứng | G8: Tỷ lệ hoàn thành | H8: Giá trị thu thực tế | I8: Tỷ lệ hoàn thành thêm dự kiến | J8: Giá trị thu thêm dự kiến
A9: 1 | B9: Red Dragon | C9: =SUM(C10:C18) -> 816000000 | D9: =SUM(D10:D18) -> 881280000 | E9: =SUM(E10:E18) -> 1 | F9: 0 | G9: =SUM(G10:G18) -> 0.45 | H9: =SUM(H10:H18) -> 396576000 | I9: =SUM(I10:I18) -> 0.5 | J9: =SUM(J10:J18) -> 440640000
A10: 1.1 | B10: Sau khi ký hợp đồng | C10: 163200000 | D10: =C10*(1+0.08) -> 176256000 | E10: 0.2 | F10: 0 | G10: =E10 -> 0.2 | H10: =D10 -> 176256000 | I10: - | J10: -
A11: 1.2 | B11: Nộp TKCS | C11: 204000000 | D11: =C11*(1+0.08) -> 220320000 | E11: 0.25 | F11: 0 | G11: =E11 -> 0.25 | H11: =D11 -> 220320000 | I11: - | J11: -
A12: 1.3 | B12: Duyệt TKCS | C12: 40800000 | D12: =C12*(1+0.08) -> 44064000 | E12: 0.05 | F12: 0 | G12: - | H12: 0 | I12: 0.05 | J12: =D12 -> 44064000
A13: 1.4 | B13: Lập hồ sơ PCCC - TKCS | C13: 40800000 | D13: =C13*(1+0.08) -> 44064000 | E13: 0.05 | F13: 0 | G13: - | H13: 0 | I13: 0.05 | J13: =D13 -> 44064000
A14: 1.5 | B14: Lập hồ sơ PCCC - TKKT | C14: 40800000 | D14: =C14*(1+0.08) -> 44064000 | E14: 0.05 | F14: 0 | G14: - | H14: 0 | I14: 0.05 | J14: =D14 -> 44064000
A15: 1.6 | B15: Nộp TKKT | C15: 204000000 | D15: =C15*(1+0.08) -> 220320000 | E15: 0.25 | F15: 0 | G15: - | H15: 0 | I15: 0.25 | J15: =D15 -> 220320000
A16: 1.7 | B16: Duyệt TKKT | C16: 40800000 | D16: =C16*(1+0.08) -> 44064000 | E16: 0.05 | F16: 0 | G16: - | H16: 0 | I16: 0.05 | J16: =D16 -> 44064000
A17: 1.8 | B17: Nộp TKTC | C17: 40800000 | D17: =C17*(1+0.08) -> 44064000 | E17: 0.05 | F17: 0 | G17: - | H17: 0 | I17: 0.05 | J17: =D17 -> 44064000
A18: 1.9 | B18: Duyệt TKTC | C18: 40800000 | D18: =C18*(1+0.08) -> 44064000 | E18: 0.05 | F18: 0 | G18: - | H18: 0 | I18: - | J18: -
A19: Lợi nhuận dự án dự kiến | C19: - | D19: - | E19: 0.26 | F19: - | G19: =E19*G9 -> 0.117 | H19: =G19*H9 -> 46399392 | I19: =E19*I9 -> 0.13 | J19: =I19*J9 -> 57283200
A20: 2 | B20: CCTP1 & CCTP 2 | C20: 5850000000 | D20: =SUM(D21:D32) -> 6397704000 | E20: =SUM(E21:E32) -> 1 | F20: 0 | G20: =SUM(G21:G32) -> 0.35 | H20: =SUM(H21:H32) -> 2239196400 | I20: =SUM(I21:I32) -> 0.45 | J20: =SUM(J21:J32) -> 2878966800
A21: 2.1 | B21: Phí huy động nhân sự | C21: 592380000 | D21: =C21*(1+0.08) -> 639770400 | E21: 0.1 | F21: 0 | G21: =E21 -> 0.1 | H21: =D21 -> 639770400 | I21: - | J21: -
A22: 2.2 | B22: Hoàn thành kiểm tra và hoàn thiện thiết kế concept hiện hữu | C22: 592380000 | D22: =C22*(1+0.08) -> 639770400 | E22: 0.1 | F22: 0 | G22: =E22 -> 0.1 | H22: =D22 -> 639770400 | I22: - | J22: -
A23: 2.3 | B23: Hoàn thành workshop với CĐT | C23: 296190000 | D23: =C23*(1+0.08) -> 319885200 | E23: 0.05 | F23: 0 | G23: 0.05 | H23: =D23 -> 319885200 | I23: - | J23: -
A24: 2.4 | B24: Sau khi bên B nộp hồ sơ hardcopy TKCS cho bên A | C24: 592380000 | D24: =C24*(1+0.08) -> 639770400 | E24: 0.1 | F24: 0 | G24: 0.1 | H24: =D24 -> 639770400 | I24: - | J24: -
A25: 2.5 | B25: CĐT phê duyệt TKCS và có VB thẩm định TKCS | C25: 592380000 | D25: =C25*(1+0.08) -> 639770400 | E25: 0.1 | F25: 0 | G25: - | H25: 0 | I25: =E25 -> 0.1 | J25: =D25 -> 639770400
A26: 2.6 | B26: Sau khi bên B nộp hồ sơ hardcopy TKKT cho bên A | C26: 592380000 | D26: =C26*(1+0.08) -> 639770400 | E26: 0.1 | F26: 0 | G26: - | H26: 0 | I26: 0.1 | J26: =D26 -> 639770400
A27: 2.7 | B27: Sau khi bên B nộp hồ sơ PCCC cho bên A | C27: 296190000 | D27: =C27*(1+0.08) -> 319885200 | E27: 0.05 | F27: 0 | G27: - | H27: 0 | I27: 0.05 | J27: =D27 -> 319885200
A28: 2.8 | B28: Sau khi CĐT phê duyệt TKKT và PCCC | C28: 592380000 | D28: =C28*(1+0.08) -> 639770400 | E28: 0.1 | F28: 0 | G28: - | H28: 0 | I28: 0.1 | J28: =D28 -> 639770400
A29: 2.9 | B29: Sau khi bên B nộp hồ sơ hardcopy TKTC ngầm cho bên A | C29: 296190000 | D29: =C29*(1+0.08) -> 319885200 | E29: 0.05 | F29: 0 | G29: - | H29: 0 | I29: 0.05 | J29: =D29 -> 319885200
A30: 2.1 | B30: Sau khi bên B nộp hồ sơ hardcopy TKTC thân cho bên A | C30: 296190000 | D30: =C30*(1+0.08) -> 319885200 | E30: 0.05 | F30: 0 | G30: - | H30: 0 | I30: 0.05 | J30: =D29 -> 319885200
A31: 2.11 | B31: Sau khi CĐT phê duyệt hồ sơ TKTC | C31: 592380000 | D31: =C31*(1+0.08) -> 639770400 | E31: 0.1 | F31: 0 | G31: - | H31: 0 | I31: - | J31: -
A32: 2.12 | B32: Sau khi dự án hoàn thành, nghiệm thu và đưa vào sử dụng | C32: 592380000 | D32: =C32*(1+0.08) -> 639770400 | E32: 0.1 | F32: 0 | G32: - | H32: 0 | I32: - | J32: -
A33: Lợi nhuận dự án dự kiến | C33: =E33*C20 -> 3451500000 | D33: - | E33: 0.59 | F33: - | G33: =E33*G20 -> 0.2065 | H33: =G33*H20 -> 4.6239406e+08 | I33: =E33*I20 -> 0.2655 | J33: =I33*J20 -> 7.6436569e+08
A34: 3 | B34: C8A | C34: 2054650000 | D34: =SUM(D35:D45) -> 2219022000 | E34: =SUM(E35:E45) -> 1 | F34: =SUM(F35:F45) -> 205465000 | G34: =SUM(G35:G45) -> 0.2 | H34: =SUM(H35:H45) -> 406820700 | I34: =SUM(I35:I45) -> 0.45 | J34: =SUM(J35:J45) -> 898703910
A35: 3.1 | B35: Tạm ứng | C35: 205465000 | D35: - | E35: - | F35: 0 | G35: 0.1 | H35: =C35 -> 205465000
A36: 3.2 | B36: Hoàn thành workshop với CĐT | C36: 205465000 | D36: =C36*(1+0.08) -> 221902200 | E36: 0.1 | F36: =C36*E36 -> 20546500 | G36: =E36 -> 0.1 | H36: =D36-F36 -> 201355700 | I36: - | J36: -
A37: 3.3 | B37: Sau khi bên B nộp hồ sơ hardcopy TKCS cho bên A | C37: 205465000 | D37: =C37*(1+0.08) -> 221902200 | E37: 0.1 | F37: 20546500 | G37: - | H37: 0 | I37: =E37 -> 0.1 | J37: =(C37-F37)*1.08 -> 199711980
A38: 3.4 | B38: CĐT phê duyệt TKCS và có VB thẩm định TKCS | C38: 205465000 | D38: =C38*(1+0.08) -> 221902200 | E38: 0.1 | F38: 20546500 | G38: - | H38: 0 | I38: =E38 -> 0.1 | J38: =(C38-F38)*1.08 -> 199711980
A39: 3.5 | B39: Sau khi bên B nộp hồ sơ PCCC cho bên A | C39: 205465000 | D39: =C39*(1+0.08) -> 221902200 | E39: 0.1 | F39: 20546500 | G39: - | H39: 0 | I39: 0.1 | J39: =(C39-F39)*1.08 -> 199711980
A40: 3.6 | B40: Sau khi bên B nộp hồ sơ hardcopy TKKT cho bên A | C40: 308197500 | D40: =C40*(1+0.08) -> 332853300 | E40: 0.15 | F40: 30819750 | G40: - | H40: 0 | I40: 0.15 | J40: =(C40-F40)*1.08 -> 299567970
A41: 3.7 | B41: Sau khi CĐT phê duyệt TKKT và PCCC | C41: 205465000 | D41: =C41*(1+0.08) -> 221902200 | E41: 0.1 | F41: 20546500 | G41: - | H41: 0 | I41: - | J41: -
A42: 3.8 | B42: Sau khi bên B nộp hồ sơ hardcopy TKTC ngầm cho bên A | C42: 102732500 | D42: =C42*(1+0.08) -> 110951100 | E42: 0.05 | F42: 10273250 | G42: - | H42: 0 | I42: - | J42: -
...

Sheet CP_VP-Overhead
B1: CHI PHÍ OVERHEAD (VĂN PHÒNG, LƯƠNG GIÁN TIẾP . . .)
B2: DỰ TRÙ TRUNG BÌNH HÀNG THÁNG | H2: Chi phí dự trù cho 14 người bao gồm 12 nhân viên chính thức và 2 quản lý
A4: STT | B4: DIỄN GIẢI | C4: THỜI GIAN (T) | D4: HỆ SỐ TG | E4: SỐ LƯỢNG | F4: CHI PHÍ (/tháng) | G4: THÀNH TIỀN (VNĐ) | H4: GHI CHÚ | J4: T6/2026 - T8/2026 | K4: T9/2025 - T4/2026 | L4: T9/2026 - T12/2026
A5: I | B5: LƯƠNG NHÂN SỰ GIÁN TIẾP | G5: =SUBTOTAL(9,G6:G8) -> 1497648000 | J5: =SUM(J6:J8) -> 374412000 | K5: =SUM(K6:K8) -> 299280000 | L5: =SUM(L6:L8) -> 499216000
A6: 1 | B6: Nhân viên dọn dẹp văn phòng | C6: 12 | D6: 1 | E6: 1 | F6: 1000000 | G6: =PRODUCT(C6:F6) -> 12000000 | H6: Bao gồm Lương quản lý doanh nghiệp, phụ cấp và bảo hiểm. | J6: =F6*3 -> 3000000 | K6: =F6*6 -> 6000000 | L6: =F6*4 -> 4000000
A7: 2 | B7: Giám đốc quản lý doanh nghiệp | C7: 12 | D7: 1 | E7: 1 | F7: =40000000*(1+60%*21.5%+50%) -> 65160000 | G7: =PRODUCT(C7:F7) -> 781920000 | J7: =F7*3 -> 195480000 | K7: =10000000*6 -> 60000000 | L7: =F7*4 -> 260640000
A8: 3 | B8: Phó giám đốc quản lý doanh nghiệp | C8: 12 | D8: 1 | E8: 1 | F8: =36000000*(1+60%*21.5%+50%) -> 58644000 | G8: =PRODUCT(C8:F8) -> 703728000 | J8: =F8*3 -> 175932000 | K8: =32000000*(1+21.5%)*6 -> 233280000 | L8: =F8*4 -> 234576000
A9: II | B9: KHẤU HAO TÀI SẢN | G9: =SUBTOTAL(9,G10:G15) -> 609720000 | J9: =SUM(J10:J15) -> 73965000 | K9: =SUM(K10:K15) -> 153930000 | L9: =SUM(L10:L15) -> 103120000
A10: 1 | B10: Máy tính sử dụng trong văn phòng | C10: 24 | D10: 1 | E10: 1 | F10: 21000000 | G10: =PRODUCT(C10:F10) -> 504000000 | H10: Đang tính đủ 14 máy tính , khấu hao 2 năm | J10: =F10*3 -> 63000000 | K10: =F10*6 -> 126000000 | L10: =F10*4 -> 84000000
A11: 2 | B11: Thiết bị lưu trữ (NAS) | C11: 24 | D11: 1 | E11: 1 | F11: 2300000 | G11: =PRODUCT(C11:F11) -> 55200000 | H11: Khấu hao 2 năm | J11: =F11*3 -> 6900000 | K11: =F11*6 -> 13800000 | L11: =F11*4 -> 9200000
A12: 3 | B12: Dịch vụ tuyển dụng (CareerViet, Vietnamwork…) | C12: 12 | D12: 2 | E12: 1 | F12: 750000 | G12: =PRODUCT(C12:F12) -> 18000000 | H12: Dịch vụ trong 6 tháng và có thể tái tiếp tục dịch vụ | J12: 0 | K12: =F12*6*2 -> 9000000 | L12: =F12*6 -> 4500000
A13: 4 | B13: Nội thất sử dụng trong văn phòng (10/2025) | C13: 24 | D13: 1 | E13: 1 | F13: 300000 | G13: =PRODUCT(C13:F13) -> 7200000 | H13: Ghế sofa, ghế đôn, bàn lớn và nhỏ, khấu hao 2 năm | J13: =F13*3 -> 900000 | K13: =F13*6 -> 1800000 | L13: =F13*4 -> 1200000
A14: 5 | B14: Cụm bàn 4 người làm việc và ghế (Đầu năm 2026) | C14: 24 | D14: 1 | E14: 1 | F14: 555000 | G14: =PRODUCT(C14:F14) -> 13320000 | H14: Một cụm 4 bàn ghế cho nhân viên, khấu hao 2 năm | J14: =F14*3 -> 1665000 | K14: =F14*6 -> 3330000 | L14: =F14*4 -> 2220000
A15: 6 | B15: 4 bộ bàn ghế (Nữa cuối năm 2026) | C15: 24 | D15: 1 | E15: 1 | F15: 500000 | G15: =PRODUCT(C15:F15) -> 12000000 | H15: Một cụm 4 bàn ghế cho nhân viên, khấu hao 2 năm | J15: =F15*3 -> 1500000 | K15: 0 | L15: =F15*4 -> 2000000
A16: III | B16: THUÊ VĂN PHÒNG | G16: =SUBTOTAL(9,G17:G23) -> 411600000 | J16: =SUM(J17:J24) -> 116850000 | K16: =SUM(K17:K24) -> 168900000 | L16: =SUM(L17:L24) -> 146300000
A17: 1 | B17: Tiền thuê văn phòng | C17: 12 | D17: 1 | E17: 1 | F17: 22000000 | G17: =PRODUCT(C17:F17) -> 264000000 | H17: Dựa trên dữ liệu hàng tháng | J17: =F17*3 -> 66000000 | K17: =F17*6 -> 132000000 | L17: =F17*4 -> 88000000
A18: 2 | B18: Tiền điện | C18: 12 | D18: 1 | E18: 1 | F18: 2500000 | G18: =PRODUCT(C18:F18) -> 30000000 | J18: =F18*3 -> 7500000 | K18: =F18*6 -> 15000000 | L18: =F18*4 -> 10000000
A19: 3 | B19: Tiền gửi xe máy | C19: 12 | D19: 12 | E19: 1 | F19: 150000 | G19: =PRODUCT(C19:F19) -> 21600000 | J19: =F19*3*13 -> 5850000 | K19: =F19*6 -> 900000 | L19: =F19*4*13 -> 7800000
A20: 4 | B20: Tiền thuê máy in | C20: 12 | D20: 1 | E20: 1 | F20: 1100000 | G20: =PRODUCT(C20:F20) -> 13200000 | H20: Hộ kinh doanh cung cấp, thay mực miễn phí | J20: =F20*3 -> 3300000 | K20: =F20*6 -> 6600000 | L20: =F20*4 -> 4400000
A21: 5 | B21: Tiền văn phòng phẩm + ký gửi hồ sơ | C21: 12 | D21: 1 | E21: 1 | F21: 1000000 | G21: =PRODUCT(C21:F21) -> 12000000 | H21: Mua giấy phục vụ in ấn thiết yếu cho văn phòng | J21: =F21*3 -> 3000000 | K21: =F21*6 -> 6000000 | L21: =F21*4 -> 4000000
A22: 6 | B22: Tiền nước uống (bình 20L) | C22: 12 | D22: 1 | E22: 1 | F22: 1400000 | G22: =PRODUCT(C22:F22) -> 16800000 | H22: Trung bình 1 tuần 5 bình nước, 1 tháng khoảng 20 bình nước và giá trung bình 1 bình khoảng 70,000VNĐ/ bình (giá gồm VAT) | J22: =F22*3 -> 4200000 | K22: =F22*6 -> 8400000 | L22: =F22*4 -> 5600000
A23: 7 | B23: Chi phí phần mềm bản quyền (Windows Pro 11, AEC student) | C23: 12 | D23: 1 | E23: 1 | F23: 4500000 | G23: =PRODUCT(C23:F23) -> 54000000 | H23: Mua 12 license Window Pro 11, 12 AEC Student và 2 Office Family | J23: =F23*6 -> 27000000 | K23: 0 | L23: =F23*1 -> 4500000
A24: 8 | B24: Chi phí phần mềm bản quyền AEC bản quyền (2 license) | C24: 12 | D24: 1 | E24: 2 | F24: 5500000 | G24: =PRODUCT(C24:F24) -> 132000000 | H24: Dự kiến mua 1 license sau khi trúng dự án mới | J24: 0 | K24: 0 | L24: =F24*4 -> 22000000
A25: IV | B25: CHI PHÍ KHÁC | G25: =SUM(G26,G27,G33,G34,G35,G36,G37:G41) -> 394840000 | J25: =SUM(J26:J41) -> 62760000 | K25: =SUM(K26:K41) -> 116420000 | L25: =SUM(L26:L41) -> 95680000
A26: 1 | B26: Tiền thưởng sinh nhật | C26: 12 | D26: 1 | E26: 1 | F26: 720000 | G26: =PRODUCT(C26:F26) -> 8640000 | H26: Nhân viên : 500,000 VNĐ/ người (9) Trưởng nhóm : 700,000 VNĐ/ người (3) Quản lý : 1,000,000 VNĐ/ người (2) | J26: =F26*3 -> 2160000 | K26: =F26*6 -> 4320000 | L26: =F26*4 -> 2880000
A27: 2 | B27: Thuê bộ phận Kế Toán | C27: 4 | D27: 1 | E27: 1 | F27: =SUM(F28:F32) -> 24100000 | G27: =PRODUCT(C27:F27) -> 96400000 | J27: =F27*1 -> 24100000 | K27: =F27*2 -> 48200000 | L27: =F27*1 -> 24100000
B28: Phí xuất hóa đơn 1 tháng | C28: 6 | D28: 1 | E28: 1 | F28: =3000000*1.1 -> 3300000 | G28: =PRODUCT(C28:F28) -> 19800000 | H28: 1 kỳ dịch vụ Kế Toán kéo dài trong 3 tháng hay 1 quý
B29: Phí tính lương | C29: 12 | D29: 1 | E29: 1 | F29: =1000000*1.1 -> 1100000 | G29: =PRODUCT(C29:F29) -> 13200000
B30: Phí tăng giảm nhân viên | C30: 1 | D30: 1 | E30: 8 | F30: =1000000*1.1 -> 1100000 | G30: =PRODUCT(C30:F30) -> 8800000
B31: Phí quyết toán thuế năm | C31: 1 | D31: 1 | E31: 1 | F31: 12000000 | G31: =PRODUCT(C31:F31) -> 12000000
B32: Phí sổ sách, dịch vụ Kế toán trưởng | C32: 12 | D32: 1 | E32: 1 | F32: 6600000 | G32: =PRODUCT(C32:F32) -> 79200000
A33: 3 | B33: Chi phí ăn uống tăng ca | C33: 6 | D33: 2 | E33: 1 | F33: 4000000 | G33: =PRODUCT(C33:F33) -> 48000000 | H33: Tăng ca không quá 6 tháng/ năm Mỗi tháng dự trù mua đồ ăn, thức uống từ siêu thị hoặc đặt đồ ăn nhanh, dự kiến 2 tuần/ lần. | J33: =F33*3 -> 12000000 | K33: =F33*6 -> 24000000 | L33: =F33*4 -> 16000000
A34: 4 | B34: Chế độ khám sức khỏe | C34: 1 | D34: 12 | E34: 1 | F34: 2000000 | G34: =PRODUCT(C34:F34) -> 24000000 | H34: Nhân viên : 1,500,000 VNĐ/ người (8) Trưởng nhóm : 1,700,000 VNĐ/ người (3) Quản lý : 2,500,000 VNĐ/ người (2) 1 năm khám sức khỏe tổng quát 1 lần | J34: 0 | K34: 0 | L34: =G34 -> 24000000
A35: 5 | B35: Chế độ teambuilding hàng năm | C35: 1 | D35: 12 | E35: 1 | F35: 2100000 | G35: =PRODUCT(C35:F35) -> 25200000 | H35: Nhân viên : 1,500,000 VNĐ/ người Trưởng nhóm : 1,700,000 VNĐ/ người Quản lý : 3,000,000 VNĐ/ người 1 năm tổ chức teambuilding 1 lần | J35: 0 | K35: 0 | L35: =G35 -> 25200000
A36: 6 | B36: Chế độ họp mặt công ty định kỳ | C36: 2 | D36: 6 | E36: 1 | F36: 3500000 | G36: =PRODUCT(C36:F36) -> 42000000 | H36: Họp mặt công ty hàng 2 tháng/ lần Tổ chức tiệc sinh nhật hàng tháng Trung bình 500k/ người | J36: =F36*1 -> 3500000 | K36: =F36*3 -> 10500000 | L36: =F36*1 -> 3500000
A37: 7 | B37: Chế độ thăm hỏi, ốm đau | C37: 1 | D37: 12 | E37: 1 | F37: 1500000 | G37: =PRODUCT(C37:F37) -> 18000000 | H37: Nhân viên : 1,000,000 VNĐ/ người/ lần Trưởng nhóm : 1,200,000 VNĐ/ người/ lần Quản lý : 2,500,000 VNĐ/ người/ lần Bệnh nặng nằm viện hoặc nghỉ ốm trên 3 ngày, dự kiến 1 người/ lần/ năm. | J37: 0 | K37: 0 | L37: 0
A38: 8 | B38: Chi phí tiếp khách, mở rộng quan hệ khách hàng | C38: 2 | D38: 1 | E38: 6 | F38: 5000000 | G38: =PRODUCT(C38:F38) -> 60000000 | H38: Dự kiến 2 tháng/ lần. Định mức : 5,000,000 VNĐ/ lần | J38: 0 | K38: 0 | L38: 0
A39: 9 | B39: Chi phí quà cáp dịp lễ cho khách hàng (Tết ta, Trung thu) | C39: 1 | D39: 2 | E39: 12 | F39: 1750000 | G39: =PRODUCT(C39:F39) -> 42000000 | H39: Định mức : - Tết ta : 1,000,000 VNĐ/ người - Dự trù 10 người - Trung thu : 1,000,000 VNĐ/ người - Dự trù 10 người | J39: =F39*12 -> 21000000 | K39: =F39*12 -> 21000000 | L39: 0
A40: 10 | B40: Chi phí quà cho nhân viên (Tết ta) | C40: 1 | D40: 1 | E40: 12 | F40: 700000 | G40: =PRODUCT(C40:F40) -> 8400000 | H40: Định mức : - Nhân viên : 600,000 VNĐ/ phần - Trưởng nhóm : 800,000 VNĐ/ phần - Quản lý : 1,500,000 VNĐ/ phần | J40: 0 | K40: =G40 -> 8400000 | L40: 0
A41: 11 | B41: Chi phí tổ chức tiệc tất niên cuối năm | C41: 1 | D41: 1 | E41: 12 | F41: 1850000 | G41: =PRODUCT(C41:F41) -> 22200000 | H41: Định mức : Nhân viên là 1,500,000 VNĐ/ người (tiệc và quà), Quản lý 2,000,000 VNĐ/ người | J41: 0 | K41: 0 | L41: 0
...

Sheet CP_NhanSu
C1: CHI PHÍ LƯƠNG - THƯỞNG NHÂN SỰ VÀ CHI PHÍ CÔNG TY CHI TRẢ THÊM CHO NHÂN SỰ
C2: DỰ TRÙ TRUNG BÌNH NĂM 2026 - TÍNH ĐẾN ĐẦU 08/ 2026
A4: STT | B4: MÃ NHÂN VIÊN | C4: HỌ VÀ TÊN | D4: VAI TRÒ | E4: PHÒNG BAN | F4: NGÀY THỬ VIỆC | G4: HỢP ĐỒNG CHÍNH THỨC | H4: MỨC LƯƠNG THỎA THUẬN | I4: MỨC ĐÓNG BHXH | J4: TỔNG LƯƠNG TRONG NĂM | L4: TỔNG THƯỞNG TRONG NĂM (≈ 3 tháng lương) | O4: BHXH CÔNG TY CHI TRẢ | Q4: KINH PHÍ CÔNG ĐOÀN CÔNG TY CHI TRẢ | S4: GHI CHÚ
J5: DỰ KIẾN | K5: THỰC TẾ HIỆN TẠI | L5: DỰ KIẾN | M5: THỰC TẾ HIỆN TẠI | N5: TỶ LỆ THƯỞNG/ LƯƠNG THỰC TẾ | O5: DỰ KIẾN | P5: THỰC TẾ HIỆN TẠI | Q5: DỰ KIẾN | R5: THỰC TẾ HIỆN TẠI
A6: I . QUẢN LÝ CẤP CAO (GIÁM ĐỐC - PHÓ GIÁM ĐỐC)
A7: 1 | B7: VONE01 | C7: Niê Đào Đức Nguyên | D7: Giám đốc | E7: BGĐ | F7: - | G7: 45943 | H7: 40000000 | I7: 24000000 | J7: =H7*12 -> 480000000 | K7: =TongHopLuongThuong_NhanSu!M6 -> 184235000 | L7: =H7*5 -> 200000000 | M7: =SUM(TongHopLuongThuong_NhanSu!N6:Q6) -> 33000000 | N7: =IFERROR(M7/K7,"-") -> 0.17911906 | O7: =I7*12*21.5% -> 61920000 | P7: =TongHopLuongThuong_NhanSu!T6 -> 23040000 | Q7: =2%*I7*12 -> 5760000 | R7: =TongHopLuongThuong_NhanSu!U6 -> 1440000 | S7: Từ 04/05/2026 mới chính thức về làm tại công ty.
A8: 2 | B8: VONE02 | C8: Hoàng Công Thao | D8: Phó Giám đốc | E8: BGĐ | F8: - | G8: 45962 | H8: 36800000 | I8: 19000000 | J8: =H8*12 -> 441600000 | K8: =TongHopLuongThuong_NhanSu!M7 -> 224515000 | L8: =H8*5 -> 184000000 | M8: =SUM(TongHopLuongThuong_NhanSu!N7:Q7) -> 109560000 | N8: =IFERROR(M8/K8,"-") -> 0.48798521 | O8: =I8*12*21.5% -> 49020000 | P8: =TongHopLuongThuong_NhanSu!T7 -> 42560000 | Q8: =2%*I8*12 -> 4560000 | R8: =TongHopLuongThuong_NhanSu!U7 -> 1140000 | S8: Tăng 10% từ 01/08/2026
A9: II . QUẢN LÝTRUNG CẤP (GIÁM ĐỐC THIẾT KẾ - KIẾN TRÚC)
B10: VONE01 | C10: Niê Đào Đức Nguyên | D10: Quản lý dự án | E10: P. Kiến Trúc | F10: - | G10: 45943
B11: VONE02 | C11: Hoàng Công Thao | D11: GĐ Thiết Kế Kiến Trúc | E11: P. Kiến Trúc | F11: - | G11: 45962
A12: II . QUẢN LÝ SƠ CẤP (TRƯỞNG NHÓM)
A13: 3 | B13: VONE06 | C13: Nguyễn Tạ Sơn Tùng | D13: Trưởng Nhóm triển khai | E13: Thiết kế triển khai | F13: 46006 | G13: 45695 | H13: 20350000 | I13: 11000000 | J13: =H13*12 -> 244200000 | K13: =TongHopLuongThuong_NhanSu!M12 -> 135696900 | L13: =H13*3 -> 61050000 | M13: =SUM(TongHopLuongThuong_NhanSu!N12:Q12) -> 21125000 | N13: =IFERROR(M13/K13,"-") -> 0.15567784 | O13: =I13*12*21.5% -> 28380000 | P13: =TongHopLuongThuong_NhanSu!T12 -> 19200000 | Q13: =2%*I13*12 -> 2640000 | R13: =TongHopLuongThuong_NhanSu!U12 -> 600000 | S13: Trưởng nhóm_Level 2. Hoàn thành 8 tháng thử thách, tăng lương 10% từ 01/08/2026 như đã hứa trong phỏng vấn tban đầu.
A14: 4 | B14: VONE10 | C14: Huỳnh Chí Hải | D14: Trưởng Nhóm triển khai | E14: Thiết kế triển khai | F14: 46106 | G14: 46167 | H14: 18500000 | I14: 11000000 | J14: =H14*12 -> 222000000 | K14: =TongHopLuongThuong_NhanSu!M16 -> 74492380 | L14: =H14*3 -> 55500000 | M14: =SUM(TongHopLuongThuong_NhanSu!N16:Q16) -> 1700000 | N14: =IFERROR(M14/K14,"-") -> 0.022821126 | O14: =I14*12*21.5% -> 28380000 | P14: =TongHopLuongThuong_NhanSu!T16 -> 6400000 | Q14: =2%*I14*12 -> 2640000 | R14: =TongHopLuongThuong_NhanSu!U16 -> 400000 | S14: Trưởng nhóm_Level 3
A15: 5 | B15: VONE03 | C15: Hồ Tâm Trí | D15: Trưởng Nhóm triển khai | E15: Thiết kế triển khai | F15: 46174 | G15: =F15+60 -> 46234 | H15: 20000000 | I15: 12000000 | J15: =H15*12 -> 240000000 | K15: =TongHopLuongThuong_NhanSu!M17 -> 34601400 | L15: =H15*3 -> 60000000 | M15: =SUM(TongHopLuongThuong_NhanSu!N17:Q17) -> 700000 | N15: =IFERROR(M15/K15,"-") -> 0.020230395 | O15: =I15*12*21.5% -> 30960000 | P15: =TongHopLuongThuong_NhanSu!T17 -> 0 | Q15: =2%*I15*12 -> 2880000 | R15: =TongHopLuongThuong_NhanSu!U17 -> 0 | S15: Trưởng nhóm_Level 3
A16: III . CHUYÊN VIÊN
A17: 6 | B17: VONE03 | C17: Ngô Đức Thịnh | D17: Kiến trúc sư triển khai | E17: Thiết kế triển khai | F17: 45964 | G17: =F17+60 -> 46024 | H17: 14000000 | I17: 8000000 | J17: =H17*12 -> 168000000 | K17: =TongHopLuongThuong_NhanSu!M9 -> 116930600 | L17: =H17*3 -> 42000000 | M17: =SUM(TongHopLuongThuong_NhanSu!N9:Q9) -> 17200000 | N17: =IFERROR(M17/K17,"-") -> 0.1470958 | O17: =I17*12*21.5% -> 20640000 | P17: =TongHopLuongThuong_NhanSu!T9 -> 17920000 | Q17: =2%*I17*12 -> 1920000 | R17: =TongHopLuongThuong_NhanSu!U9 -> 480000 | S17: Đào tạo lên vai trò Trưởng nhóm_Level 3
A18: 7 | B18: VONE04 | C18: Dương Đại Phúc | D18: Kiến trúc sư triển khai | E18: Thiết kế triển khai | F18: 45971 | G18: 46031 | H18: 13300000 | I18: 8000000 | J18: =H18*12 -> 159600000 | K18: =TongHopLuongThuong_NhanSu!M10 -> 1.0614387e+08 | L18: =H18*3 -> 39900000 | M18: =SUM(TongHopLuongThuong_NhanSu!N10:Q10) -> 16465000 | N18: =IFERROR(M18/K18,"-") -> 0.15511965 | O18: =I18*12*21.5% -> 20640000 | P18: =TongHopLuongThuong_NhanSu!T10 -> 17920000 | Q18: =2%*I18*12 -> 1920000 | R18: =TongHopLuongThuong_NhanSu!U10 -> 480000 | S18: Nhân viên_Level 2
A19: 8 | B19: VONE05 | C19: Nguyễn Hiếu Hồng Ngọc | D19: Kiến trúc sư triển khai | E19: Thiết kế triển khai | F19: 45992 | G19: 46055 | H19: 14600000 | I19: 8000000 | J19: =H19*12 -> 175200000 | K19: =TongHopLuongThuong_NhanSu!M11 -> 1.1005326e+08 | L19: =H19*3 -> 43800000 | M19: =SUM(TongHopLuongThuong_NhanSu!N11:Q11) -> 16180000 | N19: =IFERROR(M19/K19,"-") -> 0.14701973 | O19: =I19*12*21.5% -> 20640000 | P19: =TongHopLuongThuong_NhanSu!T11 -> 15360000 | Q19: =2%*I19*12 -> 1920000 | R19: =TongHopLuongThuong_NhanSu!U11 -> 480000 | S19: Nhân viên_Level 2
A20: IV . NHÂN VIÊN
A21: 9 | B21: VONE07 | C21: Nguyễn Hoàng Như Mai | D21: Kiến trúc sư triển khai | E21: Thiết kế triển khai | F21: 46099 | G21: 46161 | H21: 11000000 | I21: 6000000 | J21: =H21*12 -> 132000000 | K21: =TongHopLuongThuong_NhanSu!M13 -> 46415585 | L21: =H21*3 -> 33000000 | M21: =SUM(TongHopLuongThuong_NhanSu!N13:Q13) -> 1500000 | N21: =IFERROR(M21/K21,"-") -> 0.032316731 | O21: =I21*12*21.5% -> 15480000 | P21: =TongHopLuongThuong_NhanSu!T13 -> 4480000 | Q21: =2%*I21*12 -> 1440000 | R21: =TongHopLuongThuong_NhanSu!U13 -> 280000 | S21: Chuyên viên_Level 2
A22: 10 | B22: VONE11 | C22: Nguyễn Nhựt Khương | D22: Kiến trúc sư triển khai | E22: Thiết kế triển khai | F22: 46162 | G22: =F22+60 -> 46222 | H22: 17000000 | I22: 10000000 | J22: =H22*12 -> 204000000 | K22: =TongHopLuongThuong_NhanSu!M15 -> 38482314 | L22: =H22*3 -> 51000000 | M22: =SUM(TongHopLuongThuong_NhanSu!N15:Q15) -> 0 | N22: =IFERROR(M22/K22,"-") -> 0 | O22: =I22*12*21.5% -> 25800000 | P22: =TongHopLuongThuong_NhanSu!T15 -> 0 | Q22: =2%*I22*12 -> 2400000 | R22: =TongHopLuongThuong_NhanSu!U15 -> 0 | S22: Chuyên viên_Level 2
A23: 11 | B23: VONE08 | C23: Đỗ Quỳnh Như | D23: Kiến trúc sư triển khai | E23: Thiết kế triển khai | F23: 46161 | G23: 19/7/2026 | H23: 14000000 | I23: 8000000 | J23: =H23*12 -> 168000000 | K23: =TongHopLuongThuong_NhanSu!M14 -> 30366915 | L23: =H23*3 -> 42000000 | M23: =SUM(TongHopLuongThuong_NhanSu!N14:Q14) -> 500000 | N23: =IFERROR(M23/K23,"-") -> 0.016465288 | O23: =I23*12*21.5% -> 20640000 | P23: =TongHopLuongThuong_NhanSu!T14 -> 0 | Q23: =2%*I23*12 -> 1920000 | R23: =TongHopLuongThuong_NhanSu!U14 -> 0 | S23: Nhân viên_Level 3
A24: 12 | B24: VONE13 | C24: Thân Mạnh Tín | D24: Kiến trúc sư triển khai | E24: Thiết kế triển khai | F24: =F26 -> 46162 | G24: =F24+60 -> 46222 | H24: 19200000 | I24: 10000000 | J24: =H24*12 -> 230400000 | K24: =TongHopLuongThuong_NhanSu!M18 -> 17325000 | L24: =H24*3 -> 57600000 | M24: =SUM(TongHopLuongThuong_NhanSu!N18:Q18) -> 0 | N24: =IFERROR(M24/K24,"-") -> 0 | O24: =I24*12*21.5% -> 25800000 | P24: =TongHopLuongThuong_NhanSu!T18 -> 0 | Q24: =2%*I24*12 -> 2400000 | R24: =TongHopLuongThuong_NhanSu!U18 -> 0 | S24: Chuyên viên_Level 1
A25: V . THỰC TẬP SINH
A26: 13 | B26: VONE-TTS01 | C26: Huỳnh Thị Trúc | D26: Kiến trúc sư triển khai | E26: Thiết kế triển khai | F26: 46162 | G26: =F26+90 -> 46252 | H26: 2750000 | I26: - | J26: - | K26: - | L26: - | M26: - | N26: - | O26: - | P26: - | Q26: - | R26: - | S26: Thực tập sinh
A27: 14 | B27: VONE-TTS02 | C27: Nguyễn Thị Thanh Nhạn | D27: Kiến trúc sư triển khai | E27: Thiết kế triển khai | F27: 46162 | G27: =F27+90 -> 46252 | H27: 2750000 | I27: - | J27: - | K27: - | L27: - | M27: - | N27: - | O27: - | P27: - | Q27: - | R27: - | S27: Thực tập sinh
A28: 15 | B28: VONE-TTS03 | C28: Nguyễn Thị Như Quỳnh | D28: Kiến trúc sư triển khai | E28: Thiết kế triển khai | F28: 46162 | G28: =F28+90 -> 46252 | H28: 2750000 | I28: - | J28: - | K28: - | L28: - | M28: - | N28: - | O28: - | P28: - | Q28: - | R28: - | S28: Thực tập sinh
A29: T Ổ N G C Ộ N G | H29: =SUM(H7:H27) -> 244250000 | I29: =SUM(I7:I24) -> 135000000 | J29: =SUM(J7:J27) -> 2865000000 | K29: =SUM(K7:K27) -> 1.1192582e+09 | L29: =SUM(L7:L27) -> 869850000 | M29: =SUM(M7:M27) -> 217930000 | N29: =IFERROR(M29/K29,"-") -> 0.19470931 | O29: =SUM(O7:O27) -> 348300000 | P29: =TongHopLuongThuong_NhanSu!T19 -> 169920000 | Q29: =SUM(Q7:Q27) -> 32400000 | R29: =TongHopLuongThuong_NhanSu!U19 -> 5300000
C31: TỔNG LƯƠNG KHÔNG BAO GỒM QUẢN LÝ ĐIỀU HÀNH (GIÁM ĐỐC/PHÓ GIÁM ĐỐC) | H31: =H29-H7-H8 -> 167450000 | J31: =J29-J7-J8 -> 1943400000 | K31: =K29-K7-K8 -> 7.1050822e+08 | O31: TỔNG BHXH VÀ CÔNG ĐOÀN 2026 DỰ KIẾN NỘP NHÀ NƯỚC | Q31: =O29+Q29 -> 380700000
D32: Thưởng tối đa 3 tháng lương : - Dự án : 3-4 lần ( Định mức 0,5 tháng x hệ số ) - Tết tây : 0,5 - 1 tháng x hệ số - Tết tây : 1 tháng lương x hệ số (Tùy theo kế hoạch SXKD mà có thể bổ sung 0,5-1 tháng) ---> Đảm bảo thu nhập tăng ít nhất 30% (khoảng 3 tháng lương) Thưởng nhân viên, chuyên viên xuất sắc : 0,5 tháng lương Thưởng trưởng nhóm xuất sắc : 0,5 tháng lương | J32: (Không tính 10.5% khấu trừ từ lương của NLĐ)

Sheet TongHopLuongThuong_NhanSu
A2: BẢNG TỔNG HỢP LƯƠNG THƯỞNG CÁN BỘ NHÂN VIÊN CÔNG TY CỔ PHẦN THIẾT KẾ VONE - THÁNG 07/ 2026
A4: STT | B4: MÃ NHÂN VIÊN | C4: HỌ VÀ TÊN | D4: NĂM SINH | E4: NGÀY VÀO CÔNG TY | F4: NGÀY KẾT THÚC HĐLĐ | G4: GIAI ĐOẠN NĂM 2025 | M4: GIAI ĐOẠN NĂM 2026
G5: TỔNG LƯƠNG (VNĐ) | H5: THƯỞNG SINH NHẬT (VNĐ) | I5: THƯỞNG DỰ ÁN (VNĐ) | J5: THƯỞNG TẾT TÂY (VNĐ) | K5: THƯỞNG TẾT TA (VNĐ) | L5: TỔNG CỘNG (VNĐ) | M5: TỔNG LƯƠNG (VNĐ) | N5: THƯỞNG SINH NHẬT (VNĐ) | O5: THƯỞNG DỰ ÁN (VNĐ) | P5: THƯỞNG TẾT TÂY (VNĐ) | Q5: THƯỞNG TẾT TA (VNĐ) | R5: TỔNG CỘNG (VNĐ) | S5: TỶ LỆ LƯƠNG/ THƯỞNG | T5: BHXH CÔNG TY CHI TRẢ | U5: KPCD CÔNG TY CHI TRẢ | V5: GHI CHÚ
A6: 1 | B6: VONE01 | C6: Niê Đào Đức Nguyên | D6: 31914 | E6: 45943 | F6: - | G6: 26617500 | H6: 0 | I6: 0 | J6: 0 | K6: 0 | L6: =SUM(G6:K6) -> 26617500 | M6: 184235000 | N6: 1000000 | O6: 0 | P6: 2000000 | Q6: 30000000 | R6: =SUM(M6:Q6) -> 217235000 | S6: =SUM(N6:Q6)/M6 -> 0.17911906 | T6: 23040000 | U6: 1440000 | V6: Đóng BHXH từ tháng 05/2026, tính đến hết 07/2026. KPCD đóng từ tháng 05/2026, tính đến hết 07/2026.
A7: 2 | B7: VONE02 | C7: Hoàng Công Thao | D7: 35128 | E7: 45962 | F7: - | G7: 64125000 | H7: 0 | I7: 0 | J7: 0 | K7: 0 | L7: =SUM(G7:K7) -> 64125000 | M7: 224515000 | N7: 1000000 | O7: 10560000 | P7: 2000000 | Q7: 96000000 | R7: =SUM(M7:Q7) -> 334075000 | S7: =SUM(N7:Q7)/M7 -> 0.48798521 | T7: 42560000 | U7: 1140000 | V7: Đóng BHXH từ tháng 11/2025, tính đến hết 07/2026. KPCD đóng từ tháng 05/2026, tính đến hết 07/2026.
A8: 3 | B8: VONE03 | C8: Đỗ Công Duy | D8: 35883 | E8: 45943 | F8: 46132 | M8: 90199687 | N8: 500000 | O8: 5000000 | P8: 2000000 | Q8: 8000000 | R8: =SUM(M8:Q8) -> 105699687 | S8: =SUM(N8:Q8)/M8 -> 0.17184095 | T8: 11520000 | U8: 0 | V8: Đóng BHXH từ tháng 01/2025 đến 05/2026. Đã nghỉ việc đi định cư Australia.
A9: 4 | B9: VONE03 | C9: Ngô Đức Thịnh | D9: 36628 | E9: 46023 | F9: 46388 | G9: 22747800 | H9: 0 | I9: 0 | J9: 0 | K9: 0 | L9: =SUM(G9:K9) -> 22747800 | M9: =97955000+9828000+9147600 -> 116930600 | N9: 500000 | O9: 7700000 | P9: 2000000 | Q9: 7000000 | R9: =SUM(M9:Q9) -> 134130600 | S9: =SUM(N9:Q9)/M9 -> 0.1470958 | T9: 17920000 | U9: 480000 | V9: Đóng BHXH từ tháng 01/2026, tính đến hết 07/2026. KPCD đóng từ tháng 05/2026, tính đến hết 07/2026.
A10: 5 | B10: VONE04 | C10: Dương Đại Phúc | D10: 36916 | E10: 46032 | F10: 46396 | G10: 19493600 | H10: 0 | I10: 0 | J10: 0 | K10: 0 | L10: =SUM(G10:K10) -> 19493600 | M10: =91967448.9795918 + 7421400+6755020 -> 1.0614387e+08 | N10: 500000 | O10: 7315000 | P10: 2000000 | Q10: 6650000 | R10: =SUM(M10:Q10) -> 1.2260887e+08 | S10: =SUM(N10:Q10)/M10 -> 0.15511965 | T10: 17920000 | U10: 480000 | V10: Đóng BHXH từ tháng 01/2026, tính đến hết 07/2026. KPCD đóng từ tháng 05/2026, tính đến hết 07/2026.
A11: 6 | B11: VONE05 | C11: Nguyễn Hiếu Hồng Ngọc | D11: 36291 | E11: 46055 | F11: 46419 | G11: 12015000 | H11: 0 | I11: 0 | J11: 0 | K11: 0 | L11: =SUM(G11:K11) -> 12015000 | M11: =99280255.1020408+10773000 -> 1.1005326e+08 | N11: 500000 | O11: 8030000 | P11: 1000000 | Q11: 6650000 | R11: =SUM(M11:Q11) -> 1.2623326e+08 | S11: =SUM(N11:Q11)/M11 -> 0.14701973 | T11: 15360000 | U11: 480000 | V11: Đóng BHXH từ tháng 02/2026, tính đến hết 07/2026. KPCD đóng từ tháng 05/2026, tính đến hết 07/2026.
A12: 7 | B12: VONE06 | C12: Tạ Nguyễn Sơn Tùng | D12: 35624 | E12: 46063 | F12: 46428 | G12: 9015300 | H12: 0 | I12: 0 | J12: 0 | K12: 0 | L12: =SUM(G12:K12) -> 9015300 | M12: =127605000+8091900 -> 135696900 | N12: 700000 | O12: 10175000 | P12: 1000000 | Q12: 9250000 | R12: =SUM(M12:Q12) -> 156821900 | S12: =SUM(N12:Q12)/M12 -> 0.15567784 | T12: 19200000 | U12: 600000 | V12: Đóng BHXH từ tháng 02/2026, tính đến hết 07/2026. KPCD đóng từ tháng 05/2026, tính đến hết 07/2026.
A13: 8 | B13: VONE07 | C13: Nguyễn Hoàng Như Mai | D13: 37618 | E13: 46161 | F13: 46526 | G13: 0 | H13: 0 | I13: 0 | J13: 0 | K13: 0 | L13: =SUM(G13:K13) -> 0 | M13: 46415585 | N13: 500000 | O13: 1000000 | P13: 0 | Q13: 0 | R13: =SUM(M13:Q13) -> 47915585 | S13: =SUM(N13:Q13)/M13 -> 0.032316731 | T13: 4480000 | U13: 280000 | V13: Đóng BHXH từ tháng 06/2026, tính đến hết 07/2026. KPCD đóng từ tháng 05/2026, tính đến hết 07/2026.
A14: 9 | B14: VONE08 | C14: Đỗ Quỳnh Như | D14: 34217 | E14: 46223 | F14: 46587 | G14: 0 | H14: 0 | I14: 0 | J14: 0 | K14: 0 | L14: =SUM(G14:K14) -> 0 | M14: 30366915 | N14: 500000 | O14: 0 | P14: 0 | Q14: 0 | R14: =SUM(M14:Q14) -> 30866915 | S14: =SUM(N14:Q14)/M14 -> 0.016465288 | T14: 0 | U14: 0 | V14: Đóng BHXH từ tháng 08/2026, tính đến hết 07/2026. KPCD đóng từ tháng 05/2026, tính đến hết 07/2026.
A15: 10 | B15: VONE09 | C15: Nguyễn Nhựt Khương | D15: 34875 | E15: 46223 | F15: 46587 | G15: 0 | H15: 0 | I15: 0 | J15: 0 | K15: 0 | L15: =SUM(G15:K15) -> 0 | M15: 38482314 | N15: 0 | O15: 0 | P15: 0 | Q15: 0 | R15: =SUM(M15:Q15) -> 38482314 | S15: =SUM(N15:Q15)/M15 -> 0 | T15: 0 | U15: 0 | V15: Đóng BHXH từ tháng 08/2026, tính đến hết 07/2026. KPCD đóng từ tháng 05/2026, tính đến hết 07/2026.
A16: 11 | B16: VONE10 | C16: Huỳnh Chí Hải | D16: 35983 | E16: 46168 | F16: 46532 | G16: 0 | H16: 0 | I16: 0 | J16: 0 | K16: 0 | L16: =SUM(G16:K16) -> 0 | M16: 74492380 | N16: 700000 | O16: 1000000 | P16: 0 | Q16: 0 | R16: =SUM(M16:Q16) -> 76192380 | S16: =SUM(N16:Q16)/M16 -> 0.022821126 | T16: 6400000 | U16: 400000 | V16: Đóng BHXH từ tháng 06/2026, tính đến hết 07/2026. KPCD đóng từ tháng 05/2026, tính đến hết 07/2026.
A17: 12 | B17: VONE11 | C17: Hồ Tâm Trí | D17: 36009 | E17: 46236 | F17: 46600 | G17: 0 | H17: 0 | I17: 0 | J17: 0 | K17: 0 | L17: =SUM(G17:K17) -> 0 | M17: 34601400 | N17: 700000 | O17: 0 | P17: 0 | Q17: 0 | R17: =SUM(M17:Q17) -> 35301400 | S17: =SUM(N17:Q17)/M17 -> 0.020230395 | T17: 0 | U17: 0 | V17: Đóng BHXH từ tháng 08/2026, tính đến hết 07/2026. KPCD đóng từ tháng 05/2026, tính đến hết 07/2026.
A18: 13 | B18: VONE12 | C18: Thân Mạnh Tín | D18: 35138 | E18: 46204 | G18: 0 | H18: 0 | I18: 0 | J18: 0 | K18: 0 | L18: =SUM(G18:K18) -> 0 | M18: 17325000 | N18: 0 | O18: 0 | P18: 0 | Q18: 0 | R18: =SUM(M18:Q18) -> 17325000 | S18: =SUM(N18:Q18)/M18 -> 0 | T18: 0 | U18: 0 | V18: Đóng BHXH từ tháng 09/2026, tính đến hết 07/2026. KPCD đóng từ tháng 05/2026, tính đến hết 07/2026.
A19: TỔNG CỘNG | G19: =SUM(G6:G18) -> 154014200 | H19: =SUM(H6:H18) -> 0 | I19: =SUM(I6:I18) -> 0 | J19: =SUM(J6:J18) -> 0 | K19: =SUM(K6:K18) -> 0 | L19: =SUM(L6:L18) -> 154014200 | M19: =SUM(M6:M18) -> 1.2094579e+09 | N19: =SUM(N6:N18) -> 7100000 | ... R19: =SUM(R6:R18) -> 1.4428879e+09 | T19: =SUM(T6:T18)+11520000 -> 169920000 | U19: =SUM(U6:U18) -> 5300000 | V19: 1 . Tổng BHXH công ty chi trả (cột T) đã cộng thêm 11.520.000đ BHXH của Đỗ Công Duy (nghỉ việc T4/2026. 2 . Nguyễn Thúy Vy và Vũ Minh Mẫn (đã nghỉ việc trong năm 2026) không phát sinh BHXH do toàn bộ thời gian làm việc là thử việc.

Sheet Draft_BangNgachBacLuong
A1: CÔNG TY CỔ PHẦN THIẾT KẾ VONE | G1: BẢNG NGẠCH BẬC LƯƠNG | N1: LƯƠNG KHỞI ĐIỂM | Q1: 10000000
A2: I | B2: NGẠCH LƯƠNG 1_QUẢN LÝ CẤP CAO
A3: 1 | B3: GIÁM ĐỐC ĐIỀU HÀNH
A4: STT | B4: HẠNG MỤC | D4: MÃ KHOÁN | E4: HỆ SỐ | F4: BƯỚC | G4: 0.75 | H4: 0.85 | I4: 0.95 | J4: 1.1 | K4: 1.3 | L4: 1.4 | M4: 1.5 | N4: GHI CHÚ
F5: THAM SỐ | G5: BẬC 1 | H5: BẬC 2 | I5: BẬC 3 | J5: BẬC 4 | K5: BẬC 5 | L5: BẬC 6 | M5: BẬC 7
A7: 1.1 | B7: Lương cơ bản | D7: LCB | E7: 2 | F7: Hs*LKĐ*Bc | G7: =Q1*E7*G4 -> 15000000 | H7: =Q1*E7*H4 -> 17000000 | I7: =Q1*E7*I4 -> 19000000 | J7: =Q1*E7*J4 -> 22000000 | K7: =Q1*E7*K4 -> 26000000 | L7: =Q1*E7*L4 -> 28000000 | M7: =Q1*E7*M4 -> 30000000
A8: 1.2 | B8: Lương vị trí | D8: LVT | E8: 1 | F8: Hs*LKĐ*Bc | G8: =Q1*E8*G4 -> 7500000 | H8: =Q1*E8*H4 -> 8500000 | I8: =Q1*E8*I4 -> 9500000 | J8: =Q1*E8*J4 -> 11000000 | K8: =Q1*E8*K4 -> 13000000 | L8: =Q1*E8*L4 -> 14000000 | M8: =Q1*E8*M4 -> 15000000
A9: 1.3 | B9: Lương KPI | D9: LKPI | E9: 1 | F9: Hs*LKĐ*Bc | G9: =Q1*E9*G4 -> 7500000 | H9: =Q1*E9*H4 -> 8500000 | I9: =Q1*E9*I4 -> 9500000 | J9: =Q1*E9*J4 -> 11000000 | K9: =Q1*E9*K4 -> 13000000 | L9: =Q1*E9*L4 -> 14000000 | M9: =Q1*E9*M4 -> 15000000
A10: 1.4 | B10: Phụ cấp quản lý | D10: PCQL | E10: 1 | F10: Hs*LKĐ*Bc | G10: =Q1*E10*G4 -> 7500000 | H10: =Q1*E10*H4 -> 8500000 | I10: =Q1*E10*I4 -> 9500000 | J10: =Q1*E10*J4 -> 11000000 | K10: =Q1*E10*K4 -> 13000000 | L10: =Q1*E10*L4 -> 14000000 | M10: =Q1*E10*M4 -> 15000000
A11: 1.5 | B11: Phụ cấp trách nhiệm | D11: PCTN | E11: 1 | F11: Hs*LKĐ*Bc | G11: =Q1*E11*G4 -> 7500000 | H11: =Q1*E11*H4 -> 8500000 | I11: =Q1*E11*I4 -> 9500000 | J11: =Q1*E11*J4 -> 11000000 | K11: =Q1*E11*K4 -> 13000000 | L11: =Q1*E11*L4 -> 14000000 | M11: =Q1*E11*M4 -> 15000000
A12: 1.6 | B12: …
B13: Tổng lương & phụ cấp | G13: =SUM(G7:G12) -> 45000000 | H13: =SUM(H7:H12) -> 51000000 | I13: =SUM(I7:I12) -> 57000000 | J13: =SUM(J7:J12) -> 66000000 | K13: =SUM(K7:K12) -> 78000000 | L13: =SUM(L7:L12) -> 84000000 | M13: =SUM(M7:M12) -> 90000000
B14: Tham chiếu (nếu có)
A15: 2 | B15: PHÓ GIÁM ĐỐC ĐIỀU HÀNH
A16: STT | B16: HẠNG MỤC | D16: MÃ KHOÁN | E16: HỆ SỐ | F16: BƯỚC | G16: 0.7 | H16: 0.75 | I16: 0.8 | J16: 0.85 | K16: 0.9 | L16: 0.95 | M16: 1 | N16: GHI CHÚ
F17: THAM SỐ | G17: BẬC 1 | H17: BẬC 2 | I17: BẬC 3 | J17: BẬC 4 | K17: BẬC 5 | L17: BẬC 6 | M17: BẬC 7
A19: 2.1 | B19: Lương cơ bản | D19: LCB | E19: 1.8 | F19: Hs*LKĐ*Bc | G19: =Q1*E19*G16 -> 12600000 | H19: =Q1*E19*H16 -> 13500000 | I19: =Q1*E19*I16 -> 14400000 | J19: =Q1*E19*J16 -> 15300000 | K19: =Q1*E19*K16 -> 16200000 | L19: =Q1*E19*L16 -> 17100000 | M19: =Q1*E19*M16 -> 18000000
A20: 2.2 | B20: Lương vị trí | D20: LVT | E20: 0.8 | F20: Hs*LKĐ*Bc | G20: =Q1*E20*G16 -> 5600000 | H20: =Q1*E20*H16 -> 6000000 | I20: =E20*I16*Q1 -> 6400000 | J20: =Q1*E20*J16 -> 6800000 | K20: =Q1*E20*K16 -> 7200000 | L20: =Q1*E20*L16 -> 7600000 | M20: =Q1*E20*M16 -> 8000000
A21: 2.3 | B21: Lương KPI | D21: LKPI | E21: 0.8 | F21: Hs*LKĐ*Bc | G21: =Q1*E21*G16 -> 5600000 | H21: =Q1*E21*H16 -> 6000000 | I21: =Q1*E21*I16 -> 6400000 | J21: =Q1*E21*J16 -> 6800000 | K21: =Q1*E21*K16 -> 7200000 | L21: =Q1*E21*L16 -> 7600000 | M21: =Q1*E21*M16 -> 8000000
A22: 2.4 | B22: Phụ cấp quản lý | D22: PCQL | E22: 0.8 | F22: Hs*LKĐ*Bc | G22: =Q1*E22*G16 -> 5600000 | H22: =Q1*E22*H16 -> 6000000 | I22: =E22*Q1*I16 -> 6400000 | J22: =Q1*E22*J16 -> 6800000 | K22: =Q1*E22*K16 -> 7200000 | L22: =Q1*E22*L16 -> 7600000 | M22: =Q1*E22*M16 -> 8000000
A23: 2.5 | B23: Phụ cấp trách nhiệm | D23: PCTN | E23: 0.8 | F23: Hs*LKĐ*Bc | G23: =Q1*E23*G16 -> 5600000 | H23: =Q1*E23*H16 -> 6000000 | I23: =Q1*E23*I16 -> 6400000 | J23: =Q1*E23*J16 -> 6800000 | K23: =Q1*E23*K16 -> 7200000 | L23: =Q1*E23*L16 -> 7600000 | M23: =Q1*E23*M16 -> 8000000
A24: 2.6 | B24: …
B25: Tổng lương & phụ cấp | G25: =SUM(G19:G24) -> 35000000 | H25: =SUM(H19:H24) -> 37500000 | I25: =SUM(I19:I24) -> 40000000 | J25: =SUM(J19:J24) -> 42500000 | K25: =SUM(K19:K24) -> 45000000 | L25: =SUM(L19:L24) -> 47500000 | M25: =SUM(M19:M24) -> 50000000
B26: Tham chiếu (nếu có)
A27: II | B27: NGẠCH LƯƠNG 2_QUẢN LÝ CẤP TRUNG
A28: 1 | B28: GIÁM ĐỐC THIẾT KẾ
A29: STT | B29: HẠNG MỤC | D29: MÃ KHOÁN | E29: HỆ SỐ | F29: BƯỚC | G29: 0.5 | H29: 0.55 | I29: 0.6 | J29: 0.65 | K29: 0.7 | L29: 0.75 | M29: 0.8 | N29: GHI CHÚ
F30: THAM SỐ | G30: BẬC 1 | H30: BẬC 2 | I30: BẬC 3 | J30: BẬC 4 | K30: BẬC 5 | L30: BẬC 6 | M30: BẬC 7
A32: 3.1 | B32: Lương cơ bản | D32: LCB | E32: 1.6 | F32: Hs*LKĐ*Bc | G32: =Q1*E32*G29 -> 8000000 | H32: =Q1*E32*H29 -> 8800000 | I32: =Q1*E32*I29 -> 9600000 | J32: =Q1*E32*J29 -> 10400000 | K32: =Q1*E32*K29 -> 11200000 | L32: =Q1*E32*L29 -> 12000000 | M32: =Q1*E32*M29 -> 12800000
A33: 3.2 | B33: Lương vị trí | D33: LVT | E33: 1 | F33: Hs*LKĐ*Bc | G33: =Q1*E33*G29 -> 5000000 | H33: =Q1*E33*H29 -> 5500000 | I33: =Q1*E33*I29 -> 6000000 | J33: =Q1*E33*J29 -> 6500000 | K33: =Q1*E33*K29 -> 7000000 | L33: =Q1*E33*L29 -> 7500000 | M33: =Q1*E33*M29 -> 8000000
A34: 3.3 | B34: Lương KPI | D34: LKPI | E34: 1 | F34: Hs*LKĐ*Bc | G34: =Q1*E34*G29 -> 5000000 | H34: =Q1*E34*H29 -> 5500000 | I34: =Q1*E34*I29 -> 6000000 | J34: =Q1*E34*J29 -> 6500000 | K34: =Q1*E34*K29 -> 7000000 | L34: =Q1*E34*L29 -> 7500000 | M34: =Q1*E34*M29 -> 8000000
A35: 3.4 | B35: Phụ cấp quản lý | D35: PCQL | E35: 1 | F35: Hs*LKĐ*Bc | G35: =Q1*E35*G29 -> 5000000 | H35: =Q1*E35*H29 -> 5500000 | I35: =Q1*E35*I29 -> 6000000 | J35: =Q1*E35*J29 -> 6500000 | K35: =Q1*E35*K29 -> 7000000 | L35: =Q1*E35*L29 -> 7500000 | M35: =Q1*E35*M29 -> 8000000
A36: 3.5 | B36: Phụ cấp trách nhiệm | D36: PCTN | E36: 1 | F36: Hs*LKĐ*Bc | G36: =Q1*E36*G29 -> 5000000 | H36: =Q1*E36*H29 -> 5500000 | I36: =Q1*E36*I29 -> 6000000 | J36: =Q1*E36*J29 -> 6500000 | K36: =Q1*E36*K29 -> 7000000 | L36: =Q1*E36*L29 -> 7500000 | M36: =E36*M29*Q1 -> 8000000
A37: 3.6 | B37: …
B38: Tổng lương & phụ cấp | G38: =SUM(G32:G37) -> 28000000 | H38: =SUM(H32:H37) -> 30800000 | I38: =SUM(I32:I37) -> 33600000 | J38: =SUM(J32:J37) -> 36400000 | K38: =SUM(K32:K37) -> 39200000 | L38: =SUM(L32:L37) -> 42000000 | M38: =SUM(M32:M37) -> 44800000
B39: Tham chiếu (nếu có)
A40: 2 | B40: PHÓ GIÁM ĐỐC THIẾT KẾ
A41: STT | B41: HẠNG MỤC | D41: MÃ KHOÁN | E41: HỆ SỐ | F41: BƯỚC | G41: 0.5 | H41: 0.55 | I41: 0.6 | J41: 0.65 | K41: 0.7 | L41: 0.75 | M41: 0.8 | N41: GHI CHÚ
F42: THAM SỐ | G42: BẬC 1 | H42: BẬC 2 | I42: BẬC 3 | J42: BẬC 4 | K42: BẬC 5 | L42: BẬC 6 | M42: BẬC 7
A44: 4.1 | B44: Lương cơ bản | D44: LCB | E44: 1.6 | F44: Hs*LKĐ*Bc | G44: =Q1*E44*G41 -> 8000000 | H44: =Q1*E44*H41 -> 8800000 | I44: =Q1*E44*I41 -> 9600000 | J44: =Q1*E44*J41 -> 10400000 | K44: =Q1*E44*K41 -> 11200000 | L44: =Q1*E44*L41 -> 12000000 | M44: =Q1*E44*M41 -> 12800000
...
