Workbook

Sheet BCTC_LHA
A1: BÁO CÁO TÀI CHÍNH DỰ ÁN
A2: DỰ ÁN: LHA - CHUNG CƯ ĐẠI LỘ HÒA BÌNH
A3: NGÀY CẬP NHẬT: 17/08/2026
A5: TÀI CHÍNH
A6: Mã đối tượng | B6: Tên công việc/ hạng mục | C6: % | D6: Tạm ứng | E6: Giá trị HĐ (chưa VAT) | F6: Hoàn trả tạm ứng | G6: Thuế VAT (%) | H6: Giá trị dự kiến theo HĐ (bao gồm VAT) | I6: Thu/chi thực tế (bao gồm VAT) | J6: Ghi chú
A7: A | B7: DOANH THU | C7: =SUM(C8:C19) -> 1 | E7: =SUM(E8:E19) -> 1250000000 | H7: =SUM(H8:H19) -> 1350000000 | I7: =SUM(I8:I19) -> 135000000
A8: 1 | B8: Phí huy động nhân sự | C8: 0.1 | D8: - | E8: 125000000 | F8: 0 | G8: 0.08 | H8: =E8*(1+G8) -> 135000000 | I8: =H8 -> 135000000 | J8: 46204
A9: 2 | B9: Hoàn thành kiểm tra và hoàn thiện thiết kế concept hiện hữu | C9: 0.1 | D9: - | E9: 125000000 | F9: 0 | G9: 0.08 | H9: =E9*(1+G9) -> 135000000 | I9: 0
A10: 3 | B10: Sau khi bên B trình bày (Workshop) với Chủ đầu tư về các giải pháp chính cho Kiến Trúc giai đoạn Thiết kế cơ sở | C10: 0.05 | D10: - | E10: 62500000 | F10: 0 | G10: 0.08 | H10: =E10*(1+G10) -> 67500000 | I10: 0
A11: 4 | B11: Sau khi bên B nộp hồ sơ Hardcopy Thiết kế cơ sở Kiến trúc cho bên A | C11: 0.1 | D11: - | E11: 125000000 | F11: 0 | G11: 0.08 | H11: =E11*(1+G11) -> 135000000 | I11: 0
A12: 5 | B12: Sau khi Chủ đầu tư phê duyệt Thiết kế cơ sở Kiến Trúc và có văn bản Thẩm định TKCS | C12: 0.1 | D12: - | E12: 125000000 | F12: 0 | G12: 0.08 | H12: =E12*(1+G12) -> 135000000 | I12: 0
A13: 6 | B13: Sau khi bên B nộp hồ sơ Thiết kế kỹ thuật Kiến Trúc cho bên A | C13: 0.1 | D13: - | E13: 125000000 | F13: 0 | G13: 0.08 | H13: =E13*(1+G13) -> 135000000 | I13: 0
A14: 7 | B14: Sau khi bên B nộp hồ sơ Thiết kê PCCC cho bên A | C14: 0.05 | D14: - | E14: 62500000 | F14: 0 | G14: 0.08 | H14: =E14*(1+G14) -> 67500000 | I14: 0
A15: 8 | B15: Sau khi Chủ đầu tư phê duyệt Thiết kế kỹ thuật và Thiết kế PCCC Kiến Trúc | C15: 0.1 | D15: - | E15: 125000000 | F15: 0 | G15: 0.08 | H15: =E15*(1+G15) -> 135000000 | I15: 0
A16: 9 | B16: Sau khi bên B nộp hồ sơ TKTC Kiến Trúc phần Ngầm cho bên A | C16: 0.05 | D16: - | E16: 62500000 | F16: 0 | G16: 0.08 | H16: =E16*(1+G16) -> 67500000 | I16: 0
A17: 10 | B17: Sau khi bên B nộp hồ sơ TKTC Kiến Trúc phần Thân cho bên A | C17: 0.05 | E17: 62500000 | G17: 0.08 | H17: =E17*(1+G17) -> 67500000
A18: 11 | B18: Sau khi CĐT phê duyệt hồ sơ TKTC Kiến Trúc cho bên A | C18: 0.1 | E18: 125000000 | G18: 0.08 | H18: =E18*(1+G18) -> 135000000
A19: 12 | B19: Sản phẩm được nghiệm thu, phê duyệt | C19: 0.1 | D19: - | E19: 125000000 | F19: 0 | G19: 0.08 | H19: =E19*(1+G19) -> 135000000 | I19: 0
A20: B | B20: CHI PHÍ | E20: =SUM(E21,E23,E26,E28) -> 932599650 | H20: =SUM(H21,H23,H26,H28) -> 0 | I20: =SUM(I21,I23,I26,I28) -> 88291290
A21: B1 | B21: CHI PHÍ NHÀ THẦU PHỤ, NHÀ CUNG CẤP | E21: =SUBTOTAL(9,E22) -> 0 | H21: =SUBTOTAL(9,H22:H22) -> 0 | I21: =SUBTOTAL(9,I22:I22) -> 0
E22: 0 | H22: 0 | I22: 0
A23: B2 | B23: CHI PHÍ TIỀN LƯƠNG, THƯỞNG, PHỤ CẤP | E23: =SUBTOTAL(9,E24:E25) -> 382200340 | H23: - | I23: =SUBTOTAL(9,I24:I25) -> 63700057
A24: B2.1 | B24: Lương, thưởng, phụ cấp ( bao gồm BHXH,YT,TN,KPCD) | E24: ='LHA_ChiPhiDuAn-Overhead'!Q6 -> 382200340 | H24: - | I24: ='LHA_ChiPhiDuAn-Overhead'!Q6 * 1/6 -> 63700057
A26: B3 | B26: CHI PHÍ QLTK/ CP PHÂN BỔ KHÁC | E26: =SUBTOTAL(9,E27:E27) -> 4.2539931e+08 | H26: =SUBTOTAL(9,H27:H27) -> 0 | I26: =SUBTOTAL(9,I27:I27) -> 22507900
A27: B3.1 | B27: Chi phí overhead (phí khấu hao tài sản, phí thuê MB vp, vp phẩm, và các chi phí khác để duy trì hoạt động Admin hỗ trợ dự án tại VP công ty ) | E27: ='LHA_ChiPhiDuAn-Overhead'!Q18 -> 4.2539931e+08 | I27: ='CP_VP-Overhead'!F44*1 -> 22507900
A28: B4 | B28: CHI PHÍ DỰ PHÒNG | C28: 0.1 | E28: =E7*C28 -> 125000000 | H28: - | I28: =SUM(I29:I31) -> 2083333.3
B29: Chi phí tiếp khách, in ấn | C29: 0.3 | E29: =E28*C29 -> 37500000 | I29: 0
B30: Chi phí phần mềm | C30: 0.1 | E30: =C30*E28 -> 12500000 | I30: =E30*(1/6) -> 2083333.3
B31: Chi phí công tác, giám sát tác giả | C31: =100%-C29-C30 -> 0.6 | E31: =C31*E28 -> 75000000 | I31: 0
A32: C | B32: LỢI NHUẬN | E32: =E7-E20 -> 317400350 | I32: =I7-I20 -> 46708710
A33: D | B33: TỶ SUẤT LỢI NHUẬN TRƯỚC THƯỞNG % | E33: =E32/E7 -> 0.25392028 | I33: =I32/I7 -> 0.34599044
A34: E | B34: THƯỞNG DỰ ÁN | C34: 0.2 | E34: =ROUND(C34*E32,-6) -> 63000000 | I34: =C34*I32 -> 9341742
A35: E1 | B35: 1. Mức thưởng bằng (10% - 20%) tổng mức thưởng thực tế của dự án : E1 = (10% - 20%) X E 2. Thời gian thưởng: sau khi Hợp đồng dự án được ký kết 3. Đối tượng khen thưởng: + Nhân sự tham gia trực tiếp báo giá và thương thảo Hợp đồng. + Nhân sự tham gia kiểm tra hồ sơ TKYT (hồ sơ bản vẽ và tính toán) đảm bảo thông số đầu vào cho TKCS. | C35: 0.2 | E35: =ROUND(C35*$E$34,-6) -> 13000000
A36: E2 | B36: 1. Mức thưởng bằng (15-25%) tổng mức thưởng thực tế của dự án : E2 = (15-25%) X E 2. Thời gian thưởng: sau khi dự án hoàn thành giai đoạn thẩm định Báo cáo nghiên cứu khả thi. 3. Đối tượng khen thưởng: + Chủ nhiệm thiết kế giai đoạn triển khai + Các nhân sự trực tiếp tham gia quản lý/ triển khai KT. | C36: 0.25 | E36: =ROUND(C36*$E$34,-6) -> 16000000
A37: E3 | B37: 1. Mức thưởng bằng (15-25%) tổng mức thưởng thực tế của dự án : E3 = (15-25%) X E 2. Thời gian thưởng: sau khi dự án hoàn thành giai đoạn Xin phép xây dựng. 3. Đối tượng khen thưởng: + Chủ nhiệm thiết kế giai đoạn triển khai. + Các nhân sự trực tiếp tham gia quản lý/ triển khai KT. | C37: 0.25 | E37: =ROUND(C37*$E$34,-6) -> 16000000
A38: E4 | B38: 1. Mức thưởng bằng (10-15%) tổng mức thưởng thực tế của dự án : E4 = (10-15%) X E 2. Thời gian thưởng: sau khi dự án hoàn thành giai đoạn nghiệm thu, bàn giao đưa vào sử dụng. 3. Đối tượng khen thưởng: + Chủ nhiệm thiết kế giai đoạn triển khai. + Các nhân sự trực tiếp tham gia quản lý/ triển khai KT. | C38: 0.25 | E38: =ROUND(C38*$E$34,-6) -> 16000000
A39: E5 | B39: 1. Mức thưởng bằng 25%-35% tổng mức thưởng thực tế của dự án : E5 = (25%-35%) X E 2. Viêc trích thưởng cho quỹ thưởng cho trưởng phòng ban, các bộ phận gián tiếp (BGĐ, kế toán, hành chính…) được thực hiện như sau: - Sau khi dự án hoàn thành thẩm định báo cáo nghiên cứu khả thi: trích thưởng 50% x H. - Sau khi dự án hoàn thành giai đoạn nghiệm thu, bàn giao: trích thưởng 50% x H. 2. Thời gian thưởng: định kỳ 2 lần/ năm + Lần 1 vào cuối quý 2 + Lần 2 vào cuối quý 4. 3. Đối tượng khen thưởng: Trưởng phòng ban, các bộ phận gián tiếp (BGĐ, kế toán, hành chính…) | C39: 0.35 | E39: =ROUND(C39*$E$34,-6) -> 22000000
A41: F | B41: LỢI NHUẬN | E41: =E32-E34 -> 254400350 | I41: =I32-I34 -> 37366968
A42: G | B42: TỶ SUẤT LỢI NHUẬN % | E42: =E41/E7 -> 0.20352028 | I42: =I41/I7 -> 0.27679236
A44: III. PHÊ DUYỆT
...

Sheet LHA_ChiPhiDuAn-Overhead
B1: CHI PHÍ NHÂN SỰ VÀ HEADOFFICE
B2: Dự án: LHA - CHƯNG CƯ ĐẠI LỘ HÒA BÌNH
A4: STT | B4: DIỄN GIẢI | C4: TKCS | F4: TKKT | I4: TKTC | L4: GSTG | O4: THỜI GIAN (1ns/tháng) | P4: CHI PHÍ (/tháng) | Q4: THÀNH TIỀN (VNĐ) | R4: GHI CHÚ
C5: THỜI GIAN (T) | D5: HỆ SỐ TG | E5: SL NHÂN SỰ | F5: THỜI GIAN (T) | G5: HỆ SỐ TG | H5: SL NHÂN SỰ | I5: THỜI GIAN (T) | J5: HỆ SỐ TG | K5: SL NHÂN SỰ | L5: THỜI GIAN (T) | M5: HỆ SỐ TG | N5: SL NHÂN SỰ
A6: I | B6: CHI PHÍ NHÂN SỰ TRỰC TIẾP | Q6: =SUBTOTAL(9,Q7:Q12) -> 382200340
A7: 1 | B7: Kiến trúc sư_Trưởng nhóm (Hải) | C7: 2 | D7: 0.5 | E7: 1 | F7: 2 | G7: 0.25 | H7: 1 | I7: 2 | J7: 0.1 | K7: 1 | L7: 24 | M7: 0.1 | N7: 1 | O7: =SUM(PRODUCT(C7:E7),PRODUCT(F7:H7), PRODUCT(I7:K7),PRODUCT(L7:N7)) -> 4.1 | P7: =18500000*(1+60%*21.5%+30%) -> 26436500 | Q7: =O7*P7 -> 1.0838965e+08
A8: 2 | B8: Kiến trúc sư_Triển khai_1 (Mai) | C8: 2 | D8: 0.75 | E8: 1 | F8: 2 | G8: 0.5 | H8: 1 | I8: 2 | J8: 0.25 | K8: 1 | L8: 24 | M8: 0.1 | N8: 1 | O8: =SUM(PRODUCT(C8:E8),PRODUCT(F8:H8), PRODUCT(I8:K8),PRODUCT(L8:N8)) -> 5.4 | P8: =11000000*(1+60%*21.5%+30%) -> 15719000 | Q8: =O8*P8 -> 84882600
A9: 3 | B9: Kiến trúc sư_Triển khai_2 (Thịnh) | C9: 2 | D9: 0.5 | E9: 1 | F9: 2 | G9: 0.25 | H9: 1 | I9: 2 | J9: 0.1 | K9: 1 | L9: 24 | M9: 0 | N9: 0 | O9: =SUM(PRODUCT(C9:E9),PRODUCT(F9:H9), PRODUCT(I9:K9),PRODUCT(L9:N9)) -> 1.7 | P9: =14000000*(1+60%*21.5%+30%) -> 20006000 | Q9: =O9*P9 -> 34010200
A10: 4 | B10: Kiến trúc sư_Triển khai_2 (Ngọc) | C10: 2 | D10: 0.75 | E10: 1 | F10: 2 | G10: 0.5 | H10: 1 | I10: 2 | J10: 0.25 | K10: 1 | L10: 24 | M10: 0 | N10: 0 | O10: =SUM(PRODUCT(C10:E10),PRODUCT(F10:H10), PRODUCT(I10:K10),PRODUCT(L10:N10)) -> 3 | P10: =14600000*(1+60%*21.5%+30%) -> 20863400 | Q10: =O10*P10 -> 62590200
A11: 5 | B11: Kiến trúc sư_Triển khai_2 (Phúc) | C11: 2 | D11: 0.5 | E11: 1 | F11: 2 | G11: 0.25 | H11: 1 | I11: 2 | J11: 0.1 | K11: 1 | L11: 24 | M11: 0 | N11: 0 | O11: =SUM(PRODUCT(C11:E11),PRODUCT(F11:H11), PRODUCT(I11:K11),PRODUCT(L11:N11)) -> 1.7 | P11: =13300000*(1+60%*21.5%+30%) -> 19005700 | Q11: =O11*P11 -> 32309690
A12: 6 | B12: Kiến trúc sư_Triển khai_3 (Như) | C12: 2 | D12: 0.75 | E12: 1 | F12: 2 | G12: 0.5 | H12: 1 | I12: 2 | J12: 0.25 | K12: 1 | L12: 24 | M12: 0 | N12: 0 | O12: =SUM(PRODUCT(C12:E12),PRODUCT(F12:H12), PRODUCT(I12:K12),PRODUCT(L12:N12)) -> 3 | P12: =14000000*(1+60%*21.5%+30%) -> 20006000 | Q12: =O12*P12 -> 60018000
A13: II | B13: CHI PHÍ IN ẤN
A14: 1 | B14: In bản vẽ các giai đoạn bên ngoài | C14: 2 | D14: 1 | E14: 1 | F14: 2 | G14: 1 | H14: 1 | I14: 2 | J14: 1 | K14: 1 | L14: 1 | M14: 1 | N14: 1 | O14: 0 | P14: 0 | Q14: =O14*P14 -> 0
A15: III | B15: CHI PHÍ ĐẦU TƯ THIẾT BỊ | Q15: =SUBTOTAL(9,Q16:Q17) -> 0
A16: 1 | B16: Autocad | C16: 2 | D16: 1 | E16: 1 | F16: 2 | G16: 1 | H16: 1 | I16: 2 | J16: 1 | K16: 1 | L16: 24 | M16: 1 | N16: 1 | O16: 0 | P16: 0 | Q16: =PRODUCT(C16:P16) -> 0 | R16: Đang sử dụng bản phần mềm Revit Student.
A17: 2 | B17: Revit | C17: 2 | D17: 1 | E17: 1 | F17: 2 | G17: 1 | H17: 1 | I17: 2 | J17: 1 | K17: 1 | L17: 24 | M17: 1 | N17: 1 | O17: 0 | P17: 0 | Q17: =PRODUCT(C17:P17) -> 0
A18: IV | B18: CHI PHÍ OVERHEAD | Q18: =SUBTOTAL(9,Q19:Q19) -> 4.2539931e+08
A19: 1 | B19: Chi phí overhead tính trên nhân sự thực hiện dự án | O19: =SUM(O7:O12) -> 18.9 | P19: ='CP_VP-Overhead'!F44 -> 22507900 | Q19: =PRODUCT(C19:P19) -> 4.2539931e+08 | R19: Chi phí overhead bao gồm : Lương nhân sự gián tiếp, phí khấu hao tài sản, phí thuê MB vp , vp phẩm, và các chi phí khác để duy trì hoạt động Admin hỗ trợ dự án tại VP công ty).

Sheet CP_VP-Overhead
B1: CHI PHÍ OVERHEAD (VĂN PHÒNG, LƯƠNG GIÁN TIẾP . . .)
B2: DỰ TRÙ TRUNG BÌNH HÀNG THÁNG | H2: Chi phí dự trù cho 14 người bao gồm 12 nhân viên chính thức và 2 quản lý
A4: STT | B4: DIỄN GIẢI | C4: THỜI GIAN (T) | D4: HỆ SỐ TG | E4: SỐ LƯỢNG | F4: CHI PHÍ (/tháng) | G4: THÀNH TIỀN (VNĐ) | H4: GHI CHÚ | J4: T6/2026 - T8/2026 | K4: T9/2025 - T4/2026 | L4: T9/2026 - T12/2026
A5: I | B5: LƯƠNG NHÂN SỰ GIÁN TIẾP | G5: =SUBTOTAL(9,G6:G8) -> 1497648000 | J5: =SUM(J6:J8) -> 374412000 | K5: =SUM(K6:K8) -> 299280000 | L5: =SUM(L6:L8) -> 499216000
A6: 1 | B6: Nhân viên dọn dẹp văn phòng | C6: 12 | D6: 1 | E6: 1 | F6: 1000000 | G6: =PRODUCT(C6:F6) -> 12000000 | H6: Bao gồm Lương quản lý doanh nghiệp, phụ cấp và bảo hiểm. | J6: =F6*3 -> 3000000 | K6: =F6*6 -> 6000000 | L6: =F6*4 -> 4000000
A7: 2 | B7: Giám đốc quản lý doanh nghiệp | C7: 12 | D7: 1 | E7: 1 | F7: =40000000*(1+60%*21.5%+50%) -> 65160000 | G7: =PRODUCT(C7:F7) -> 781920000 | J7: =F7*3 -> 195480000 | K7: =10000000*6 -> 60000000 | L7: =F7*4 -> 260640000
A8: 3 | B8: Phó giám đốc quản lý doanh nghiệp | C8: 12 | D8: 1 | E8: 1 | F8: =36000000*(1+60%*21.5%+50%) -> 58644000 | G8: =PRODUCT(C8:F8) -> 703728000 | J8: =F8*3 -> 175932000 | K8: =32000000*(1+21.5%)*6 -> 233280000 | L8: =F8*4 -> 234576000
A9: II | B9: KHẤU HAO TÀI SẢN | G9: =SUBTOTAL(9,G10:G15) -> 609720000 | J9: =SUM(J10:J15) -> 73965000 | K9: =SUM(K10:K15) -> 153930000 | L9: =SUM(L10:L15) -> 103120000
A10: 1 | B10: Máy tính sử dụng trong văn phòng | C10: 24 | D10: 1 | E10: 1 | F10: 21000000 | G10: =PRODUCT(C10:F10) -> 504000000 | H10: Đang tính đủ 14 máy tính , khấu hao 2 năm | J10: =F10*3 -> 63000000 | K10: =F10*6 -> 126000000 | L10: =F10*4 -> 84000000
A11: 2 | B11: Thiết bị lưu trữ (NAS) | C11: 24 | D11: 1 | E11: 1 | F11: 2300000 | G11: =PRODUCT(C11:F11) -> 55200000 | H11: Khấu hao 2 năm | J11: =F11*3 -> 6900000 | K11: =F11*6 -> 13800000 | L11: =F11*4 -> 9200000
A12: 3 | B12: Dịch vụ tuyển dụng (CareerViet, Vietnamwork…) | C12: 12 | D12: 2 | E12: 1 | F12: 750000 | G12: =PRODUCT(C12:F12) -> 18000000 | H12: Dịch vụ trong 6 tháng và có thể tái tiếp tục dịch vụ | J12: 0 | K12: =F12*6*2 -> 9000000 | L12: =F12*6 -> 4500000
A13: 4 | B13: Nội thất sử dụng trong văn phòng (10/2025) | C13: 24 | D13: 1 | E13: 1 | F13: 300000 | G13: =PRODUCT(C13:F13) -> 7200000 | H13: Ghế sofa, ghế đôn, bàn lớn và nhỏ, khấu hao 2 năm | J13: =F13*3 -> 900000 | K13: =F13*6 -> 1800000 | L13: =F13*4 -> 1200000
A14: 5 | B14: Cụm bàn 4 người làm việc và ghế (Đầu năm 2026) | C14: 24 | D14: 1 | E14: 1 | F14: 555000 | G14: =PRODUCT(C14:F14) -> 13320000 | H14: Một cụm 4 bàn ghế cho nhân viên, khấu hao 2 năm | J14: =F14*3 -> 1665000 | K14: =F14*6 -> 3330000 | L14: =F14*4 -> 2220000
A15: 6 | B15: 4 bộ bàn ghế (Nữa cuối năm 2026) | C15: 24 | D15: 1 | E15: 1 | F15: 500000 | G15: =PRODUCT(C15:F15) -> 12000000 | H15: Một cụm 4 bàn ghế cho nhân viên, khấu hao 2 năm | J15: =F15*3 -> 1500000 | K15: 0 | L15: =F15*4 -> 2000000
A16: III | B16: THUÊ VĂN PHÒNG | G16: =SUBTOTAL(9,G17:G23) -> 411600000 | J16: =SUM(J17:J24) -> 116850000 | K16: =SUM(K17:K24) -> 168900000 | L16: =SUM(L17:L24) -> 146300000
A17: 1 | B17: Tiền thuê văn phòng | C17: 12 | D17: 1 | E17: 1 | F17: 22000000 | G17: =PRODUCT(C17:F17) -> 264000000 | H17: Dựa trên dữ liệu hàng tháng | J17: =F17*3 -> 66000000 | K17: =F17*6 -> 132000000 | L17: =F17*4 -> 88000000
A18: 2 | B18: Tiền điện | C18: 12 | D18: 1 | E18: 1 | F18: 2500000 | G18: =PRODUCT(C18:F18) -> 30000000 | J18: =F18*3 -> 7500000 | K18: =F18*6 -> 15000000 | L18: =F18*4 -> 10000000
A19: 3 | B19: Tiền gửi xe máy | C19: 12 | D19: 12 | E19: 1 | F19: 150000 | G19: =PRODUCT(C19:F19) -> 21600000 | J19: =F19*3*13 -> 5850000 | K19: =F19*6 -> 900000 | L19: =F19*4*13 -> 7800000
A20: 4 | B20: Tiền thuê máy in | C20: 12 | D20: 1 | E20: 1 | F20: 1100000 | G20: =PRODUCT(C20:F20) -> 13200000 | H20: Hộ kinh doanh cung cấp, thay mực miễn phí | J20: =F20*3 -> 3300000 | K20: =F20*6 -> 6600000 | L20: =F20*4 -> 4400000
A21: 5 | B21: Tiền văn phòng phẩm + ký gửi hồ sơ | C21: 12 | D21: 1 | E21: 1 | F21: 1000000 | G21: =PRODUCT(C21:F21) -> 12000000 | H21: Mua giấy phục vụ in ấn thiết yếu cho văn phòng | J21: =F21*3 -> 3000000 | K21: =F21*6 -> 6000000 | L21: =F21*4 -> 4000000
A22: 6 | B22: Tiền nước uống (bình 20L) | C22: 12 | D22: 1 | E22: 1 | F22: 1400000 | G22: =PRODUCT(C22:F22) -> 16800000 | H22: Trung bình 1 tuần 5 bình nước, 1 tháng khoảng 20 bình nước và giá trung bình 1 bình khoảng 70,000VNĐ/ bình (giá gồm VAT) | J22: =F22*3 -> 4200000 | K22: =F22*6 -> 8400000 | L22: =F22*4 -> 5600000
A23: 7 | B23: Chi phí phần mềm bản quyền (Windows Pro 11, AEC student) | C23: 12 | D23: 1 | E23: 1 | F23: 4500000 | G23: =PRODUCT(C23:F23) -> 54000000 | H23: Mua 12 license Window Pro 11, 12 AEC Student và 2 Office Family | J23: =F23*6 -> 27000000 | K23: 0 | L23: =F23*1 -> 4500000
A24: 8 | B24: Chi phí phần mềm bản quyền AEC bản quyền (2 license) | C24: 12 | D24: 1 | E24: 2 | F24: 5500000 | G24: =PRODUCT(C24:F24) -> 132000000 | H24: Dự kiến mua 1 license sau khi trúng dự án mới | J24: 0 | K24: 0 | L24: =F24*4 -> 22000000
A25: IV | B25: CHI PHÍ KHÁC | G25: =SUM(G26,G27,G33,G34,G35,G36,G37:G41) -> 394840000 | J25: =SUM(J26:J41) -> 62760000 | K25: =SUM(K26:K41) -> 116420000 | L25: =SUM(L26:L41) -> 95680000
A26: 1 | B26: Tiền thưởng sinh nhật | C26: 12 | D26: 1 | E26: 1 | F26: 720000 | G26: =PRODUCT(C26:F26) -> 8640000 | H26: Nhân viên : 500,000 VNĐ/ người (9) Trưởng nhóm : 700,000 VNĐ/ người (3) Quản lý : 1,000,000 VNĐ/ người (2) | J26: =F26*3 -> 2160000 | K26: =F26*6 -> 4320000 | L26: =F26*4 -> 2880000
A27: 2 | B27: Thuê bộ phận Kế Toán | C27: 4 | D27: 1 | E27: 1 | F27: =SUM(F28:F32) -> 24100000 | G27: =PRODUCT(C27:F27) -> 96400000 | J27: =F27*1 -> 24100000 | K27: =F27*2 -> 48200000 | L27: =F27*1 -> 24100000
B28: Phí xuất hóa đơn 1 tháng | C28: 6 | D28: 1 | E28: 1 | F28: =3000000*1.1 -> 3300000 | G28: =PRODUCT(C28:F28) -> 19800000 | H28: 1 kỳ dịch vụ Kế Toán kéo dài trong 3 tháng hay 1 quý
B29: Phí tính lương | C29: 12 | D29: 1 | E29: 1 | F29: =1000000*1.1 -> 1100000 | G29: =PRODUCT(C29:F29) -> 13200000
B30: Phí tăng giảm nhân viên | C30: 1 | D30: 1 | E30: 8 | F30: =1000000*1.1 -> 1100000 | G30: =PRODUCT(C30:F30) -> 8800000
B31: Phí quyết toán thuế năm | C31: 1 | D31: 1 | E31: 1 | F31: 12000000 | G31: =PRODUCT(C31:F31) -> 12000000
B32: Phí sổ sách, dịch vụ Kế toán trưởng | C32: 12 | D32: 1 | E32: 1 | F32: 6600000 | G32: =PRODUCT(C32:F32) -> 79200000
A33: 3 | B33: Chi phí ăn uống tăng ca | C33: 6 | D33: 2 | E33: 1 | F33: 4000000 | G33: =PRODUCT(C33:F33) -> 48000000 | H33: Tăng ca không quá 6 tháng/ năm Mỗi tháng dự trù mua đồ ăn, thức uống từ siêu thị hoặc đặt đồ ăn nhanh, dự kiến 2 tuần/ lần. | J33: =F33*3 -> 12000000 | K33: =F33*6 -> 24000000 | L33: =F33*4 -> 16000000
A34: 4 | B34: Chế độ khám sức khỏe | C34: 1 | D34: 12 | E34: 1 | F34: 2000000 | G34: =PRODUCT(C34:F34) -> 24000000 | H34: Nhân viên : 1,500,000 VNĐ/ người (8) Trưởng nhóm : 1,700,000 VNĐ/ người (3) Quản lý : 2,500,000 VNĐ/ người (2) 1 năm khám sức khỏe tổng quát 1 lần | J34: 0 | K34: 0 | L34: =G34 -> 24000000
A35: 5 | B35: Chế độ teambuilding hàng năm | C35: 1 | D35: 12 | E35: 1 | F35: 2100000 | G35: =PRODUCT(C35:F35) -> 25200000 | H35: Nhân viên : 1,500,000 VNĐ/ người Trưởng nhóm : 1,700,000 VNĐ/ người Quản lý : 3,000,000 VNĐ/ người 1 năm tổ chức teambuilding 1 lần | J35: 0 | K35: 0 | L35: =G35 -> 25200000
A36: 6 | B36: Chế độ họp mặt công ty định kỳ | C36: 2 | D36: 6 | E36: 1 | F36: 3500000 | G36: =PRODUCT(C36:F36) -> 42000000 | H36: Họp mặt công ty hàng 2 tháng/ lần Tổ chức tiệc sinh nhật hàng tháng Trung bình 500k/ người | J36: =F36*1 -> 3500000 | K36: =F36*3 -> 10500000 | L36: =F36*1 -> 3500000
A37: 7 | B37: Chế độ thăm hỏi, ốm đau | C37: 1 | D37: 12 | E37: 1 | F37: 1500000 | G37: =PRODUCT(C37:F37) -> 18000000 | H37: Nhân viên : 1,000,000 VNĐ/ người/ lần Trưởng nhóm : 1,200,000 VNĐ/ người/ lần Quản lý : 2,500,000 VNĐ/ người/ lần Bệnh nặng nằm viện hoặc nghỉ ốm trên 3 ngày, dự kiến 1 người/ lần/ năm. | J37: 0 | K37: 0 | L37: 0
A38: 8 | B38: Chi phí tiếp khách, mở rộng quan hệ khách hàng | C38: 2 | D38: 1 | E38: 6 | F38: 5000000 | G38: =PRODUCT(C38:F38) -> 60000000 | H38: Dự kiến 2 tháng/ lần. Định mức : 5,000,000 VNĐ/ lần | J38: 0 | K38: 0 | L38: 0
A39: 9 | B39: Chi phí quà cáp dịp lễ cho khách hàng (Tết ta, Trung thu) | C39: 1 | D39: 2 | E39: 12 | F39: 1750000 | G39: =PRODUCT(C39:F39) -> 42000000 | H39: Định mức : - Tết ta : 1,000,000 VNĐ/ người - Dự trù 10 người - Trung thu : 1,000,000 VNĐ/ người - Dự trù 10 người | J39: =F39*12 -> 21000000 | K39: =F39*12 -> 21000000 | L39: 0
A40: 10 | B40: Chi phí quà cho nhân viên (Tết ta) | C40: 1 | D40: 1 | E40: 12 | F40: 700000 | G40: =PRODUCT(C40:F40) -> 8400000 | H40: Định mức : - Nhân viên : 600,000 VNĐ/ phần - Trưởng nhóm : 800,000 VNĐ/ phần - Quản lý : 1,500,000 VNĐ/ phần | J40: 0 | K40: =G40 -> 8400000 | L40: 0
A41: 11 | B41: Chi phí tổ chức tiệc tất niên cuối năm | C41: 1 | D41: 1 | E41: 12 | F41: 1850000 | G41: =PRODUCT(C41:F41) -> 22200000 | H41: Định mức : Nhân viên là 1,500,000 VNĐ/ người (tiệc và quà), Quản lý 2,000,000 VNĐ/ người | J41: 0 | K41: 0 | L41: 0
...

Sheet QuyDoiPhanMemVeDuAn
A2: QUY ĐỔI GIÁ TRỊ PHẦN MỀM VỀ CÁC DỰ ÁN HIỆN TẠI | H2: GIÁ TRỊ PHẦN MỀM TƯƠNG ỨNG
A7: DỰ ÁN | B7: CCTP 1&2 | C7: RED DRAGON | D7: C8A | E7: LHA | F7: DQMH | H7: STT | I7: TÊN PHẦN MỀM | J7: SỐ LƯỢNG | K7: GIÁ ĐƠN VỊ | L7: THÀNH TIỀN
A8: GÍA TRỊ HỢP ĐỒNG | B8: 5850000000 | C8: 816000000 | D8: 2054650000 | E8: 1250000000 | F8: 10000000000 | H8: 1 | I8: AEC | J8: 2 | K8: 65000000 | L8: =K8*J8 -> 130000000
A9: HỆ SỐ QUY ĐỔI | B9: =B8/C8 -> 7.1691176 | C9: 1 | D9: =D8/C8 -> 2.5179534 | E9: =E8/C8 -> 1.5318627 | F9: =F8/C8 -> 12.254902 | H9: 2 | I9: Windows Pro 11 | J9: 12 | K9: 3380000 | L9: =K9*J9 -> 40560000
A10: TỔNG CHI PHÍ PHẦN MỀM | B10: =L12 -> 181900000 | H10: 3 | I10: AEC Student | J10: 12 | K10: 450000 | L10: =K10*J10 -> 5400000
A11: CHI PHÍ PHÂN BỔ CÁC DỰ ÁN | B11: =C11*B9 -> 53283944 | C11: =(B10/SUM(B9:F9)) -> 7432427.1 | D11: =C11*D9 -> 18714505 | E11: =C11*E9 -> 11385458 | F11: =C11*F9 -> 91083665 | H11: 4 | I11: Office 365 Family | J11: 3 | K11: 1980000 | L11: =K11*J11 -> 5940000
H12: TỔNG CỘNG | L12: =SUM(L8:L11) -> 181900000
